Workbook

Sheet 가정
A1: 다이소몰 매출 시뮬레이션 — 가정
A2: 노란 셀만 수정합니다. 시나리오는 A의 레버 3개 조합으로만 정의되고, B~D는 모든 시나리오에 똑같이 적용됩니다.
A4: A. 레버 — 시나리오를 정의하는 유일한 입력
A5: 레버 | B5: 단위 | C5: S1 현재 기준 | D5: S2 익일 | E5: S3 익일+무배 | F5: S4 +회원 확대 | G5: 연결 과제 | H5: 근거
A6: 완전 익일배송 (컷오프 개선) | B6: 1=적용 | C6: 0 | D6: 1 | E6: 1 | F6: 1 | G6: 세종 안정화 · 자정 마감 익일 도착 | H6: 정책
A7: 무료배송 임계 | B7: 원 | C7: 30000 | D7: 30000 | E7: 25000 | F7: 25000 | G7: 무료배송 기준 인하 | H7: 정책
A8: 회원 확대 (간편가입) | B8: 1=적용 | C8: 0 | D8: 0 | E8: 0 | F8: 1 | G8: SNS · 이메일 간편가입, 본인인증 이탈 해소 | H8: 정책
A10: B. 레버 효과 — 레버를 켰을 때 무엇이 얼마나 바뀌는가 (공통)
A11: 항목 | B11: 단위 | C11: 값 | G11: 설명 | H11: 근거
A12: 익일배송 → 잔존율 상승 | B12: %p | C12: 0.019 | G12: 11.1% → 13.0%. 서서히 (물류 효과 도달 개월수에 걸쳐) | H12: 목표
A13: 익일배송 → 구매빈도 상승 | B13: % | C13: 0.2 | G13: 1.289 → 1.547건. 서서히 | H13: 목표
A14: 익일배송 → 가입 감쇠 완화 | B14: %p/월 | C14: 0.002 | G14: -0.5% → -0.3%/월. 서서히 | H14: 추정
A15: 무배 인하 → 즉시 주문 증가율 (1차) | B15: % | C15: 0.086 | G15: 인하 시점에 한 번에. 8월 분포 기준 +8.6%, 올라붙는 모수 확대 반영 시 +24.3% | H15: 추정
A16: 무배 인하 → 인하 후 객단가 (1차) | B16: 원 | C16: 29800 | G16: 인하 시점에 한 번에. +8.6%일 때 29,800원, +24.3%일 때 29,400원 | H16: 추정
A17: 무배 인하 → 잔존율 추가 상승 (2차) | B17: %p | C17: 0.02 | G17: 13.0% → 15.0%. 서서히 | H17: 목표
A18: 무배 인하 → 가입 감쇠 추가 완화 (2차) | B18: %p/월 | C18: 0.002 | G18: -0.3% → -0.1%/월. 서서히 | H18: 추정
A19: 회원 확대 → 월 가입 증가 | B19: % | C19: 0.28 | G19: 본인인증 이탈(26.5%)을 전부 회수하면 최대 +36% | H19: 목표
A21: C. 불확실성 — 고객 반응을 모르는 부분 (공통, 값을 흔들어 민감도 확인)
A22: 항목 | B22: 단위 | C22: 값 | G22: 설명 | H22: 근거
A23: 기존 고객 반응도 | B23: % | C23: 1 | G23: 잔존율 상승이 2026년 이전 고객에게 적용되는 비율 | H23: 미측정
A24: 간편가입자 첫구매 전환율 (기존 대비) | B24: % | C24: 1 | G24: 100% = 기존 가입자와 같은 비율로 첫구매 | H24: 미측정
A26: D. 기준값 — 확인된 사실과 시점 (공통)
A27: 항목 | B27: 단위 | C27: 값 | G27: 설명 | H27: 근거
A28: 세종 안정화 월차 | B28: 월차 | C28: 6 | G28: 6 = 2027년 6월. 익일배송 효과 시작 | H28: 계획
A29: 무배 인하 월차 | B29: 월차 | C29: 7 | G29: 12 = 2027년 12월 | H29: 계획
A30: 물류 효과 도달 개월수 | B30: 개월 | C30: 48 | G30: 시작 월부터 목표치까지 선형 도달 | H30: 추정
A31: 간편가입 오픈 월차 | B31: 월차 | C31: 5 | G31: 5 = 2027년 5월 | H31: 계획
A32: 회원 확대 도달 개월수 | B32: 개월 | C32: 12 | G32: 가입 증가가 목표치에 이르는 기간 | H32: 추정
A33: 2026.12 누적 구매고객 | B33: 만명 | C33: 406 | G33: 2026-08 실측 358.5만 + 9~12월 신규 | H33: 실측+추정
A34: 2026.12 회원수 | B34: 만명 | C34: 1022 | G34: 2026-08 926만 + 4개월 가입 | H34: 실측+추정
A35: 월 가입 시작값 | B35: 만명/월 | C35: 20 | G35: 에어브릿지 가입 이벤트 (앱+웹, 중복 가능) | H35: 실측
A36: 첫구매 전환율 | B36: % | C36: 0.5 | G36: 월 가입 24만 → 신규 구매 12만 | H36: 추정
A37: 기본 가입 증감률 | B37: %/월 | C37: -0.005 | G37: 신규 25개월 횡보 후 완만한 감쇠 가정 | H37: 추정
A38: 기본 잔존율 | B38: % | C38: 0.111 | G38: 33개 코호트 M4~M12 안정화 구간 | H38: 실측
A39: 기본 구매빈도 | B39: 건/월 | C39: 1.289 | G39: 주문/구매고객, 33개월 고정 | H39: 실측
... A43: 2026년 매출 | B43: 억원 | C43: 2300 | G43: 성장률 계산용 | H43: 예상
A45: 계산 순서
A46: ① 진행도 = 레버 × (현재 월차 − 시작 월차 + 1) ÷ 도달 개월수 (0~1, 서서히 오르는 효과)
A47: ② 무배 적용 = 무배 인하 월차부터 1 (한 번에 붙는 1차 효과: 즉시 주문 증가, 객단가 하락)
A48: ③ 월 가입 = 기본 가입 추세 × (1 + 회원확대 진행도 × 가입 증가) / 신규 구매 = 기본 추세 × 전환율 × (1 + 회원확대 진행도 × 가입 증가 × 간편가입자 전환율)
...

Sheet S1_현재기준
A1: S1 현재 기준
A2: 레버 값은 가정 시트 A에서, 나머지는 B~D에서 가져옵니다. 이 시트는 수정하지 마십시오.
A3: 월차 | B3: 연도 | C3: 월 | D3: 익일 진행도 | E3: 무배 진행도 | F3: 무배 적용 | G3: 회원확대 진행도 | H3: 가입 증감률 | I3: 기본 가입 추세 (만명) | J3: 월 가입 (만명) | K3: 신규 구매고객 (만명) | L3: 잔존율 신규 코호트 | M3: 잔존율 기존 고객 | N3: 2027~ 누적 (월초, 만명) | O3: 활동 구매고객 (만명) | P3: 익일 효과 빈도 | Q3: 즉시 주문 배수 | R3: 구매빈도 (건/월) | S3: 구매건수 (만건) | T3: 객단가 (원) | U3: 택배매출 (억원) | V3: 총매출 (억원) | W3: 누적 구매고객 (만명) | X3: 미전환 회원 (만명) | Y3: 회원수 (만명) | Z3: 활동×익일빈도 (보조)
A4: 1 | B4: 2027 | C4: 1 | D4: =가정!$C$6*MIN(1,MAX(0,(A4-가정!$C$28+1)/가정!$C$30)) -> 0 | E4: =IF(가정!$C$7<30000,1,0)*MIN(1,MAX(0,(A4-가정!$C$29+1)/가정!$C$30)) -> 0 | F4: =IF(가정!$C$7<30000,1,0)*IF(A4>=가정!$C$29,1,0) -> 0 | G4: =가정!$C$8*MIN(1,MAX(0,(A4-가정!$C$31+1)/가정!$C$32)) -> 0 | H4: =가정!$C$37+D4*가정!$C$14+E4*가정!$C$18 -> -0.005 | I4: =가정!$C$35 -> 20 | J4: =I4*(1+G4*가정!$C$19) -> 20 | K4: =I4*가정!$C$36*(1+G4*가정!$C$19*가정!$C$24) -> 10 | L4: =가정!$C$38+D4*가정!$C$12+E4*가정!$C$17 -> 0.111 | M4: =가정!$C$38+가정!$C$23*(L4-가정!$C$38) -> 0.111 | N4: =0 -> 0 | O4: =K4+가정!$C$33*M4+N4*L4 -> 55.066 | P4: =가정!$C$39*(1+D4*가정!$C$13) -> 1.289 | Q4: =1+F4*가정!$C$15 -> 1 | R4: =P4*Q4 -> 1.289 | S4: =O4*R4 -> 70.980074 | T4: =IF(F4=1,가정!$C$16,가정!$C$40) -> 31846 | U4: =S4*T4/10000 -> 226.04314 | V4: =U4/(1-가정!$C$41)*가정!$C$42 -> 237.94015 | W4: =가정!$C$33+N4+K4 -> 416 | X4: =(가정!$C$34-가정!$C$33)+J4-K4 -> 626 | Y4: =W4+X4 -> 1042 | Z4: =O4*P4 -> 70.980074
A5: 2 | B5: 2027 | C5: 2 | D5: =가정!$C$6*MIN(1,MAX(0,(A5-가정!$C$28+1)/가정!$C$30)) -> 0 | E5: =IF(가정!$C$7<30000,1,0)*MIN(1,MAX(0,(A5-가정!$C$29+1)/가정!$C$30)) -> 0 | F5: =IF(가정!$C$7<30000,1,0)*IF(A5>=가정!$C$29,1,0) -> 0 | G5: =가정!$C$8*MIN(1,MAX(0,(A5-가정!$C$31+1)/가정!$C$32)) -> 0 | H5: =가정!$C$37+D5*가정!$C$14+E5*가정!$C$18 -> -0.005 | I5: =I4*(1+H5) -> 19.9 | J5: =I5*(1+G5*가정!$C$19) -> 19.9 | K5: =I5*가정!$C$36*(1+G5*가정!$C$19*가정!$C$24) -> 9.95 | L5: =가정!$C$38+D5*가정!$C$12+E5*가정!$C$17 -> 0.111 | M5: =가정!$C$38+가정!$C$23*(L5-가정!$C$38) -> 0.111 | N5: =N4+K4 -> 10 | O5: =K5+가정!$C$33*M5+N5*L5 -> 56.126 | P5: =가정!$C$39*(1+D5*가정!$C$13) -> 1.289 | Q5: =1+F5*가정!$C$15 -> 1 | R5: =P5*Q5 -> 1.289 | S5: =O5*R5 -> 72.346414 | T5: =IF(F5=1,가정!$C$16,가정!$C$40) -> 31846 | U5: =S5*T5/10000 -> 230.39439 | V5: =U5/(1-가정!$C$41)*가정!$C$42 -> 242.52041 | W5: =가정!$C$33+N5+K5 -> 425.95 | X5: =X4+J5-K5 -> 635.95 | Y5: =W5+X5 -> 1061.9 | Z5: =O5*P5 -> 72.346414
A6: 3 | B6: 2027 | C6: 3 | D6: =가정!$C$6*MIN(1,MAX(0,(A6-가정!$C$28+1)/가정!$C$30)) -> 0 | E6: =IF(가정!$C$7<30000,1,0)*MIN(1,MAX(0,(A6-가정!$C$29+1)/가정!$C$30)) -> 0 | F6: =IF(가정!$C$7<30000,1,0)*IF(A6>=가정!$C$29,1,0) -> 0 | G6: =가정!$C$8*MIN(1,MAX(0,(A6-가정!$C$31+1)/가정!$C$32)) -> 0 | H6: =가정!$C$37+D6*가정!$C$14+E6*가정!$C$18 -> -0.005 | I6: =I5*(1+H6) -> 19.8005 | J6: =I6*(1+G6*가정!$C$19) -> 19.8005 | K6: =I6*가정!$C$36*(1+G6*가정!$C$19*가정!$C$24) -> 9.90025 | L6: =가정!$C$38+D6*가정!$C$12+E6*가정!$C$17 -> 0.111 | M6: =가정!$C$38+가정!$C$23*(L6-가정!$C$38) -> 0.111 | N6: =N5+K5 -> 19.95 | O6: =K6+가정!$C$33*M6+N6*L6 -> 57.1807 | P6: =가정!$C$39*(1+D6*가정!$C$13) -> 1.289 | Q6: =1+F6*가정!$C$15 -> 1 | R6: =P6*Q6 -> 1.289 | S6: =O6*R6 -> 73.705922 | T6: =IF(F6=1,가정!$C$16,가정!$C$40) -> 31846 | U6: =S6*T6/10000 -> 234.72388 | V6: =U6/(1-가정!$C$41)*가정!$C$42 -> 247.07777 | W6: =가정!$C$33+N6+K6 -> 435.85025 | X6: =X5+J6-K6 -> 645.85025 | Y6: =W6+X6 -> 1081.7005 | Z6: =O6*P6 -> 73.705922
A7: 4 | B7: 2027 | C7: 4 | D7: =가정!$C$6*MIN(1,MAX(0,(A7-가정!$C$28+1)/가정!$C$30)) -> 0 | E7: =IF(가정!$C$7<30000,1,0)*MIN(1,MAX(0,(A7-가정!$C$29+1)/가정!$C$30)) -> 0 | F7: =IF(가정!$C$7<30000,1,0)*IF(A7>=가정!$C$29,1,0) -> 0 | G7: =가정!$C$8*MIN(1,MAX(0,(A7-가정!$C$31+1)/가정!$C$32)) -> 0 | H7: =가정!$C$37+D7*가정!$C$14+E7*가정!$C$18 -> -0.005 | I7: =I6*(1+H7) -> 19.701497 | J7: =I7*(1+G7*가정!$C$19) -> 19.701497 | K7: =I7*가정!$C$36*(1+G7*가정!$C$19*가정!$C$24) -> 9.8507487 | L7: =가정!$C$38+D7*가정!$C$12+E7*가정!$C$17 -> 0.111 | M7: =가정!$C$38+가정!$C$23*(L7-가정!$C$38) -> 0.111 | N7: =N6+K6 -> 29.85025 | O7: =K7+가정!$C$33*M7+N7*L7 -> 58.230127 | P7: =가정!$C$39*(1+D7*가정!$C$13) -> 1.289 | Q7: =1+F7*가정!$C$15 -> 1 | R7: =P7*Q7 -> 1.289 | S7: =O7*R7 -> 75.058633 | T7: =IF(F7=1,가정!$C$16,가정!$C$40) -> 31846 | U7: =S7*T7/10000 -> 239.03172 | V7: =U7/(1-가정!$C$41)*가정!$C$42 -> 251.61234 | W7: =가정!$C$33+N7+K7 -> 445.701 | X7: =X6+J7-K7 -> 655.701 | Y7: =W7+X7 -> 1101.402 | Z7: =O7*P7 -> 75.058633
A8: 5 | B8: 2027 | C8: 5 | D8: =가정!$C$6*MIN(1,MAX(0,(A8-가정!$C$28+1)/가정!$C$30)) -> 0 | E8: =IF(가정!$C$7<30000,1,0)*MIN(1,MAX(0,(A8-가정!$C$29+1)/가정!$C$30)) -> 0 | F8: =IF(가정!$C$7<30000,1,0)*IF(A8>=가정!$C$29,1,0) -> 0 | G8: =가정!$C$8*MIN(1,MAX(0,(A8-가정!$C$31+1)/가정!$C$32)) -> 0 | H8: =가정!$C$37+D8*가정!$C$14+E8*가정!$C$18 -> -0.005 | I8: =I7*(1+H8) -> 19.60299 | J8: =I8*(1+G8*가정!$C$19) -> 19.60299 | K8: =I8*가정!$C$36*(1+G8*가정!$C$19*가정!$C$24) -> 9.801495 | L8: =가정!$C$38+D8*가정!$C$12+E8*가정!$C$17 -> 0.111 | M8: =가정!$C$38+가정!$C$23*(L8-가정!$C$38) -> 0.111 | N8: =N7+K7 -> 39.700999 | O8: =K8+가정!$C$33*M8+N8*L8 -> 59.274306 | P8: =가정!$C$39*(1+D8*가정!$C$13) -> 1.289 | Q8: =1+F8*가정!$C$15 -> 1 | R8: =P8*Q8 -> 1.289 | S8: =O8*R8 -> 76.40458 | T8: =IF(F8=1,가정!$C$16,가정!$C$40) -> 31846 | U8: =S8*T8/10000 -> 243.31803 | V8: =U8/(1-가정!$C$41)*가정!$C$42 -> 256.12424 | W8: =가정!$C$33+N8+K8 -> 455.50249 | X8: =X7+J8-K8 -> 665.50249 | Y8: =W8+X8 -> 1121.005 | Z8: =O8*P8 -> 76.40458
A9: 6 | B9: 2027 | C9: 6 | D9: =가정!$C$6*MIN(1,MAX(0,(A9-가정!$C$28+1)/가정!$C$30)) -> 0 | E9: =IF(가정!$C$7<30000,1,0)*MIN(1,MAX(0,(A9-가정!$C$29+1)/가정!$C$30)) -> 0 | F9: =IF(가정!$C$7<30000,1,0)*IF(A9>=가정!$C$29,1,0) -> 0 | G9: =가정!$C$8*MIN(1,MAX(0,(A9-가정!$C$31+1)/가정!$C$32)) -> 0 | H9: =가정!$C$37+D9*가정!$C$14+E9*가정!$C$18 -> -0.005 | I9: =I8*(1+H9) -> 19.504975 | J9: =I9*(1+G9*가정!$C$19) -> 19.504975 | K9: =I9*가정!$C$36*(1+G9*가정!$C$19*가정!$C$24) -> 9.7524875 | L9: =가정!$C$38+D9*가정!$C$12+E9*가정!$C$17 -> 0.111 | M9: =가정!$C$38+가정!$C$23*(L9-가정!$C$38) -> 0.111 | N9: =N8+K8 -> 49.502494 | O9: =K9+가정!$C$33*M9+N9*L9 -> 60.313264 | P9: =가정!$C$39*(1+D9*가정!$C$13) -> 1.289 | Q9: =1+F9*가정!$C$15 -> 1 | R9: =P9*Q9 -> 1.289 | S9: =O9*R9 -> 77.743798 | T9: =IF(F9=1,가정!$C$16,가정!$C$40) -> 31846 | U9: =S9*T9/10000 -> 247.5829 | V9: =U9/(1-가정!$C$41)*가정!$C$42 -> 260.61358 | W9: =가정!$C$33+N9+K9 -> 465.25498 | X9: =X8+J9-K9 -> 675.25498 | Y9: =W9+X9 -> 1140.51 | Z9: =O9*P9 -> 77.743798
A10: 7 | B10: 2027 | C10: 7 | D10: =가정!$C$6*MIN(1,MAX(0,(A10-가정!$C$28+1)/가정!$C$30)) -> 0 | E10: =IF(가정!$C$7<30000,1,0)*MIN(1,MAX(0,(A10-가정!$C$29+1)/가정!$C$30)) -> 0 | F10: =IF(가정!$C$7<30000,1,0)*IF(A10>=가정!$C$29,1,0) -> 0 | G10: =가정!$C$8*MIN(1,MAX(0,(A10-가정!$C$31+1)/가정!$C$32)) -> 0 | H10: =가정!$C$37+D10*가정!$C$14+E10*가정!$C$18 -> -0.005 | I10: =I9*(1+H10) -> 19.40745 | J10: =I10*(1+G10*가정!$C$19) -> 19.40745 | K10: =I10*가정!$C$36*(1+G10*가정!$C$19*가정!$C$24) -> 9.7037251 | L10: =가정!$C$38+D10*가정!$C$12+E10*가정!$C$17 -> 0.111 | M10: =가정!$C$38+가정!$C$23*(L10-가정!$C$38) -> 0.111 | N10: =N9+K9 -> 59.254981 | O10: =K10+가정!$C$33*M10+N10*L10 -> 61.347028 | P10: =가정!$C$39*(1+D10*가정!$C$13) -> 1.289 | Q10: =1+F10*가정!$C$15 -> 1 | R10: =P10*Q10 -> 1.289 | S10: =O10*R10 -> 79.076319 | T10: =IF(F10=1,가정!$C$16,가정!$C$40) -> 31846 | U10: =S10*T10/10000 -> 251.82645 | V10: =U10/(1-가정!$C$41)*가정!$C$42 -> 265.08047 | W10: =가정!$C$33+N10+K10 -> 474.95871 | X10: =X9+J10-K10 -> 684.95871 | Y10: =W10+X10 -> 1159.9174 | Z10: =O10*P10 -> 79.076319
A11: 8 | B11: 2027 | C11: 8 | D11: =가정!$C$6*MIN(1,MAX(0,(A11-가정!$C$28+1)/가정!$C$30)) -> 0 | E11: =IF(가정!$C$7<30000,1,0)*MIN(1,MAX(0,(A11-가정!$C$29+1)/가정!$C$30)) -> 0 | F11: =IF(가정!$C$7<30000,1,0)*IF(A11>=가정!$C$29,1,0) -> 0 | G11: =가정!$C$8*MIN(1,MAX(0,(A11-가정!$C$31+1)/가정!$C$32)) -> 0 | H11: =가정!$C$37+D11*가정!$C$14+E11*가정!$C$18 -> -0.005 | I11: =I10*(1+H11) -> 19.310413 | J11: =I11*(1+G11*가정!$C$19) -> 19.310413 | K11: =I11*가정!$C$36*(1+G11*가정!$C$19*가정!$C$24) -> 9.6552065 | L11: =가정!$C$38+D11*가정!$C$12+E11*가정!$C$17 -> 0.111 | M11: =가정!$C$38+가정!$C$23*(L11-가정!$C$38) -> 0.111 | N11: =N10+K10 -> 68.958706 | O11: =K11+가정!$C$33*M11+N11*L11 -> 62.375623 | P11: =가정!$C$39*(1+D11*가정!$C$13) -> 1.289 | Q11: =1+F11*가정!$C$15 -> 1 | R11: =P11*Q11 -> 1.289 | S11: =O11*R11 -> 80.402178 | T11: =IF(F11=1,가정!$C$16,가정!$C$40) -> 31846 | U11: =S11*T11/10000 -> 256.04878 | V11: =U11/(1-가정!$C$41)*가정!$C$42 -> 269.52503 | W11: =가정!$C$33+N11+K11 -> 484.61391 | X11: =X10+J11-K11 -> 694.61391 | Y11: =W11+X11 -> 1179.2278 | Z11: =O11*P11 -> 80.402178
A12: 9 | B12: 2027 | C12: 9 | D12: =가정!$C$6*MIN(1,MAX(0,(A12-가정!$C$28+1)/가정!$C$30)) -> 0 | E12: =IF(가정!$C$7<30000,1,0)*MIN(1,MAX(0,(A12-가정!$C$29+1)/가정!$C$30)) -> 0 | F12: =IF(가정!$C$7<30000,1,0)*IF(A12>=가정!$C$29,1,0) -> 0 | G12: =가정!$C$8*MIN(1,MAX(0,(A12-가정!$C$31+1)/가정!$C$32)) -> 0 | H12: =가정!$C$37+D12*가정!$C$14+E12*가정!$C$18 -> -0.005 | I12: =I11*(1+H12) -> 19.213861 | J12: =I12*(1+G12*가정!$C$19) -> 19.213861 | K12: =I12*가정!$C$36*(1+G12*가정!$C$19*가정!$C$24) -> 9.6069304 | L12: =가정!$C$38+D12*가정!$C$12+E12*가정!$C$17 -> 0.111 | M12: =가정!$C$38+가정!$C$23*(L12-가정!$C$38) -> 0.111 | N12: =N11+K11 -> 78.613913 | O12: =K12+가정!$C$33*M12+N12*L12 -> 63.399075 | P12: =가정!$C$39*(1+D12*가정!$C$13) -> 1.289 | Q12: =1+F12*가정!$C$15 -> 1 | R12: =P12*Q12 -> 1.289 | S12: =O12*R12 -> 81.721407 | T12: =IF(F12=1,가정!$C$16,가정!$C$40) -> 31846 | U12: =S12*T12/10000 -> 260.24999 | V12: =U12/(1-가정!$C$41)*가정!$C$42 -> 273.94736 | W12: =가정!$C$33+N12+K12 -> 494.22084 | X12: =X11+J12-K12 -> 704.22084 | Y12: =W12+X12 -> 1198.4417 | Z12: =O12*P12 -> 81.721407
A13: 10 | B13: 2027 | C13: 10 | D13: =가정!$C$6*MIN(1,MAX(0,(A13-가정!$C$28+1)/가정!$C$30)) -> 0 | E13: =IF(가정!$C$7<30000,1,0)*MIN(1,MAX(0,(A13-가정!$C$29+1)/가정!$C$30)) -> 0 | F13: =IF(가정!$C$7<30000,1,0)*IF(A13>=가정!$C$29,1,0) -> 0 | G13: =가정!$C$8*MIN(1,MAX(0,(A13-가정!$C$31+1)/가정!$C$32)) -> 0 | H13: =가정!$C$37+D13*가정!$C$14+E13*가정!$C$18 -> -0.005 | I13: =I12*(1+H13) -> 19.117792 | J13: =I13*(1+G13*가정!$C$19) -> 19.117792 | K13: =I13*가정!$C$36*(1+G13*가정!$C$19*가정!$C$24) -> 9.5588958 | L13: =가정!$C$38+D13*가정!$C$12+E13*가정!$C$17 -> 0.111 | M13: =가정!$C$38+가정!$C$23*(L13-가정!$C$38) -> 0.111 | N13: =N12+K12 -> 88.220843 | O13: =K13+가정!$C$33*M13+N13*L13 -> 64.417409 | P13: =가정!$C$39*(1+D13*가정!$C$13) -> 1.289 | Q13: =1+F13*가정!$C$15 -> 1 | R13: =P13*Q13 -> 1.289 | S13: =O13*R13 -> 83.034041 | T13: =IF(F13=1,가정!$C$16,가정!$C$40) -> 31846 | U13: =S13*T13/10000 -> 264.43021 | V13: =U13/(1-가정!$C$41)*가정!$C$42 -> 278.34759 | W13: =가정!$C$33+N13+K13 -> 503.77974 | X13: =X12+J13-K13 -> 713.77974 | Y13: =W13+X13 -> 1217.5595 | Z13: =O13*P13 -> 83.034041
A14: 11 | B14: 2027 | C14: 11 | D14: =가정!$C$6*MIN(1,MAX(0,(A14-가정!$C$28+1)/가정!$C$30)) -> 0 | E14: =IF(가정!$C$7<30000,1,0)*MIN(1,MAX(0,(A14-가정!$C$29+1)/가정!$C$30)) -> 0 | F14: =IF(가정!$C$7<30000,1,0)*IF(A14>=가정!$C$29,1,0) -> 0 | G14: =가정!$C$8*MIN(1,MAX(0,(A14-가정!$C$31+1)/가정!$C$32)) -> 0 | H14: =가정!$C$37+D14*가정!$C$14+E14*가정!$C$18 -> -0.005 | I14: =I13*(1+H14) -> 19.022203 | J14: =I14*(1+G14*가정!$C$19) -> 19.022203 | K14: =I14*가정!$C$36*(1+G14*가정!$C$19*가정!$C$24) -> 9.5111013 | L14: =가정!$C$38+D14*가정!$C$12+E14*가정!$C$17 -> 0.111 | M14: =가정!$C$38+가정!$C$23*(L14-가정!$C$38) -> 0.111 | N14: =N13+K13 -> 97.779739 | O14: =K14+가정!$C$33*M14+N14*L14 -> 65.430652 | P14: =가정!$C$39*(1+D14*가정!$C$13) -> 1.289 | Q14: =1+F14*가정!$C$15 -> 1 | R14: =P14*Q14 -> 1.289 | S14: =O14*R14 -> 84.340111 | T14: =IF(F14=1,가정!$C$16,가정!$C$40) -> 31846 | U14: =S14*T14/10000 -> 268.58952 | V14: =U14/(1-가정!$C$41)*가정!$C$42 -> 282.72581 | W14: =가정!$C$33+N14+K14 -> 513.29084 | X14: =X13+J14-K14 -> 723.29084 | Y14: =W14+X14 -> 1236.5817 | Z14: =O14*P14 -> 84.340111
A15: 12 | B15: 2027 | C15: 12 | D15: =가정!$C$6*MIN(1,MAX(0,(A15-가정!$C$28+1)/가정!$C$30)) -> 0 | E15: =IF(가정!$C$7<30000,1,0)*MIN(1,MAX(0,(A15-가정!$C$29+1)/가정!$C$30)) -> 0 | F15: =IF(가정!$C$7<30000,1,0)*IF(A15>=가정!$C$29,1,0) -> 0 | G15: =가정!$C$8*MIN(1,MAX(0,(A15-가정!$C$31+1)/가정!$C$32)) -> 0 | H15: =가정!$C$37+D15*가정!$C$14+E15*가정!$C$18 -> -0.005 | I15: =I14*(1+H15) -> 18.927092 | J15: =I15*(1+G15*가정!$C$19) -> 18.927092 | K15: =I15*가정!$C$36*(1+G15*가정!$C$19*가정!$C$24) -> 9.4635458 | L15: =가정!$C$38+D15*가정!$C$12+E15*가정!$C$17 -> 0.111 | M15: =가정!$C$38+가정!$C$23*(L15-가정!$C$38) -> 0.111 | N15: =N14+K14 -> 107.29084 | O15: =K15+가정!$C$33*M15+N15*L15 -> 66.438829 | P15: =가정!$C$39*(1+D15*가정!$C$13) -> 1.289 | Q15: =1+F15*가정!$C$15 -> 1 | R15: =P15*Q15 -> 1.289 | S15: =O15*R15 -> 85.639651 | T15: =IF(F15=1,가정!$C$16,가정!$C$40) -> 31846 | U15: =S15*T15/10000 -> 272.72803 | V15: =U15/(1-가정!$C$41)*가정!$C$42 -> 287.08214 | W15: =가정!$C$33+N15+K15 -> 522.75439 | X15: =X14+J15-K15 -> 732.75439 | Y15: =W15+X15 -> 1255.5088 | Z15: =O15*P15 -> 85.639651
A16: 13 | B16: 2028 | C16: 1 | D16: =가정!$C$6*MIN(1,MAX(0,(A16-가정!$C$28+1)/가정!$C$30)) -> 0 | E16: =IF(가정!$C$7<30000,1,0)*MIN(1,MAX(0,(A16-가정!$C$29+1)/가정!$C$30)) -> 0 | F16: =IF(가정!$C$7<30000,1,0)*IF(A16>=가정!$C$29,1,0) -> 0 | G16: =가정!$C$8*MIN(1,MAX(0,(A16-가정!$C$31+1)/가정!$C$32)) -> 0 | H16: =가정!$C$37+D16*가정!$C$14+E16*가정!$C$18 -> -0.005 | I16: =I15*(1+H16) -> 18.832456 | J16: =I16*(1+G16*가정!$C$19) -> 18.832456 | K16: =I16*가정!$C$36*(1+G16*가정!$C$19*가정!$C$24) -> 9.4162281 | L16: =가정!$C$38+D16*가정!$C$12+E16*가정!$C$17 -> 0.111 | M16: =가정!$C$38+가정!$C$23*(L16-가정!$C$38) -> 0.111 | N16: =N15+K15 -> 116.75439 | O16: =K16+가정!$C$33*M16+N16*L16 -> 67.441965 | P16: =가정!$C$39*(1+D16*가정!$C$13) -> 1.289 | Q16: =1+F16*가정!$C$15 -> 1 | R16: =P16*Q16 -> 1.289 | S16: =O16*R16 -> 86.932693 | T16: =IF(F16=1,가정!$C$16,가정!$C$40) -> 31846 | U16: =S16*T16/10000 -> 276.84585 | V16: =U16/(1-가정!$C$41)*가정!$C$42 -> 291.41669 | W16: =가정!$C$33+N16+K16 -> 532.17061 | X16: =X15+J16-K16 -> 742.17061 | Y16: =W16+X16 -> 1274.3412 | Z16: =O16*P16 -> 86.932693
... A63: 60 | B63: 2031 | C63: 12 | D63: =가정!$C$6*MIN(1,MAX(0,(A63-가정!$C$28+1)/가정!$C$30)) -> 0 | E63: =IF(가정!$C$7<30000,1,0)*MIN(1,MAX(0,(A63-가정!$C$29+1)/가정!$C$30)) -> 0 | F63: =IF(가정!$C$7<30000,1,0)*IF(A63>=가정!$C$29,1,0) -> 0 | G63: =가정!$C$8*MIN(1,MAX(0,(A63-가정!$C$31+1)/가정!$C$32)) -> 0 | H63: =가정!$C$37+D63*가정!$C$14+E63*가정!$C$18 -> -0.005 | I63: =I62*(1+H63) -> 14.879617 | J63: =I63*(1+G63*가정!$C$19) -> 14.879617 | K63: =I63*가정!$C$36*(1+G63*가정!$C$19*가정!$C$24) -> 7.4398086 | L63: =가정!$C$38+D63*가정!$C$12+E63*가정!$C$17 -> 0.111 | M63: =가정!$C$38+가정!$C$23*(L63-가정!$C$38) -> 0.111 | N63: =N62+K62 -> 512.03828 | O63: =K63+가정!$C$33*M63+N63*L63 -> 109.34206 | P63: =가정!$C$39*(1+D63*가정!$C$13) -> 1.289 | Q63: =1+F63*가정!$C$15 -> 1 | R63: =P63*Q63 -> 1.289 | S63: =O63*R63 -> 140.94191 | T63: =IF(F63=1,가정!$C$16,가정!$C$40) -> 31846 | U63: =S63*T63/10000 -> 448.84361 | V63: =U63/(1-가정!$C$41)*가정!$C$42 -> 472.46696 | W63: =가정!$C$33+N63+K63 -> 925.47808 | X63: =X62+J63-K63 -> 1135.4781 | Y63: =W63+X63 -> 2060.9562 | Z63: =O63*P63 -> 140.94191

Sheet S2_익일
A1: S2 익일배송
A2: 레버 값은 가정 시트 A에서, 나머지는 B~D에서 가져옵니다. 이 시트는 수정하지 마십시오.
A3: 월차 | B3: 연도 | C3: 월 | D3: 익일 진행도 | E3: 무배 진행도 | F3: 무배 적용 | G3: 회원확대 진행도 | H3: 가입 증감률 | I3: 기본 가입 추세 (만명) | J3: 월 가입 (만명) | K3: 신규 구매고객 (만명) | L3: 잔존율 신규 코호트 | M3: 잔존율 기존 고객 | N3: 2027~ 누적 (월초, 만명) | O3: 활동 구매고객 (만명) | P3: 익일 효과 빈도 | Q3: 즉시 주문 배수 | R3: 구매빈도 (건/월) | S3: 구매건수 (만건) | T3: 객단가 (원) | U3: 택배매출 (억원) | V3: 총매출 (억원) | W3: 누적 구매고객 (만명) | X3: 미전환 회원 (만명) | Y3: 회원수 (만명) | Z3: 활동×익일빈도 (보조)
A4: 1 | B4: 2027 | C4: 1 | D4: =가정!$D$6*MIN(1,MAX(0,(A4-가정!$C$28+1)/가정!$C$30)) -> 0 | E4: =IF(가정!$D$7<30000,1,0)*MIN(1,MAX(0,(A4-가정!$C$29+1)/가정!$C$30)) -> 0 | F4: =IF(가정!$D$7<30000,1,0)*IF(A4>=가정!$C$29,1,0) -> 0 | G4: =가정!$D$8*MIN(1,MAX(0,(A4-가정!$C$31+1)/가정!$C$32)) -> 0 | H4: =가정!$C$37+D4*가정!$C$14+E4*가정!$C$18 -> -0.005 | I4: =가정!$C$35 -> 20 | J4: =I4*(1+G4*가정!$C$19) -> 20 | K4: =I4*가정!$C$36*(1+G4*가정!$C$19*가정!$C$24) -> 10 | L4: =가정!$C$38+D4*가정!$C$12+E4*가정!$C$17 -> 0.111 | M4: =가정!$C$38+가정!$C$23*(L4-가정!$C$38) -> 0.111 | N4: =0 -> 0 | O4: =K4+가정!$C$33*M4+N4*L4 -> 55.066 | P4: =가정!$C$39*(1+D4*가정!$C$13) -> 1.289 | Q4: =1+F4*가정!$C$15 -> 1 | R4: =P4*Q4 -> 1.289 | S4: =O4*R4 -> 70.980074 | T4: =IF(F4=1,가정!$C$16,가정!$C$40) -> 31846 | U4: =S4*T4/10000 -> 226.04314 | V4: =U4/(1-가정!$C$41)*가정!$C$42 -> 237.94015 | W4: =가정!$C$33+N4+K4 -> 416 | X4: =(가정!$C$34-가정!$C$33)+J4-K4 -> 626 | Y4: =W4+X4 -> 1042 | Z4: =O4*P4 -> 70.980074
A5: 2 | B5: 2027 | C5: 2 | D5: =가정!$D$6*MIN(1,MAX(0,(A5-가정!$C$28+1)/가정!$C$30)) -> 0 | E5: =IF(가정!$D$7<30000,1,0)*MIN(1,MAX(0,(A5-가정!$C$29+1)/가정!$C$30)) -> 0 | F5: =IF(가정!$D$7<30000,1,0)*IF(A5>=가정!$C$29,1,0) -> 0 | G5: =가정!$D$8*MIN(1,MAX(0,(A5-가정!$C$31+1)/가정!$C$32)) -> 0 | H5: =가정!$C$37+D5*가정!$C$14+E5*가정!$C$18 -> -0.005 | I5: =I4*(1+H5) -> 19.9 | J5: =I5*(1+G5*가정!$C$19) -> 19.9 | K5: =I5*가정!$C$36*(1+G5*가정!$C$19*가정!$C$24) -> 9.95 | L5: =가정!$C$38+D5*가정!$C$12+E5*가정!$C$17 -> 0.111 | M5: =가정!$C$38+가정!$C$23*(L5-가정!$C$38) -> 0.111 | N5: =N4+K4 -> 10 | O5: =K5+가정!$C$33*M5+N5*L5 -> 56.126 | P5: =가정!$C$39*(1+D5*가정!$C$13) -> 1.289 | Q5: =1+F5*가정!$C$15 -> 1 | R5: =P5*Q5 -> 1.289 | S5: =O5*R5 -> 72.346414 | T5: =IF(F5=1,가정!$C$16,가정!$C$40) -> 31846 | U5: =S5*T5/10000 -> 230.39439 | V5: =U5/(1-가정!$C$41)*가정!$C$42 -> 242.52041 | W5: =가정!$C$33+N5+K5 -> 425.95 | X5: =X4+J5-K5 -> 635.95 | Y5: =W5+X5 -> 1061.9 | Z5: =O5*P5 -> 72.346414
A6: 3 | B6: 2027 | C6: 3 | D6: =가정!$D$6*MIN(1,MAX(0,(A6-가정!$C$28+1)/가정!$C$30)) -> 0 | E6: =IF(가정!$D$7<30000,1,0)*MIN(1,MAX(0,(A6-가정!$C$29+1)/가정!$C$30)) -> 0 | F6: =IF(가정!$D$7<30000,1,0)*IF(A6>=가정!$C$29,1,0) -> 0 | G6: =가정!$D$8*MIN(1,MAX(0,(A6-가정!$C$31+1)/가정!$C$32)) -> 0 | H6: =가정!$C$37+D6*가정!$C$14+E6*가정!$C$18 -> -0.005 | I6: =I5*(1+H6) -> 19.8005 | J6: =I6*(1+G6*가정!$C$19) -> 19.8005 | K6: =I6*가정!$C$36*(1+G6*가정!$C$19*가정!$C$24) -> 9.90025 | L6: =가정!$C$38+D6*가정!$C$12+E6*가정!$C$17 -> 0.111 | M6: =가정!$C$38+가정!$C$23*(L6-가정!$C$38) -> 0.111 | N6: =N5+K5 -> 19.95 | O6: =K6+가정!$C$33*M6+N6*L6 -> 57.1807 | P6: =가정!$C$39*(1+D6*가정!$C$13) -> 1.289 | Q6: =1+F6*가정!$C$15 -> 1 | R6: =P6*Q6 -> 1.289 | S6: =O6*R6 -> 73.705922 | T6: =IF(F6=1,가정!$C$16,가정!$C$40) -> 31846 | U6: =S6*T6/10000 -> 234.72388 | V6: =U6/(1-가정!$C$41)*가정!$C$42 -> 247.07777 | W6: =가정!$C$33+N6+K6 -> 435.85025 | X6: =X5+J6-K6 -> 645.85025 | Y6: =W6+X6 -> 1081.7005 | Z6: =O6*P6 -> 73.705922
A7: 4 | B7: 2027 | C7: 4 | D7: =가정!$D$6*MIN(1,MAX(0,(A7-가정!$C$28+1)/가정!$C$30)) -> 0 | E7: =IF(가정!$D$7<30000,1,0)*MIN(1,MAX(0,(A7-가정!$C$29+1)/가정!$C$30)) -> 0 | F7: =IF(가정!$D$7<30000,1,0)*IF(A7>=가정!$C$29,1,0) -> 0 | G7: =가정!$D$8*MIN(1,MAX(0,(A7-가정!$C$31+1)/가정!$C$32)) -> 0 | H7: =가정!$C$37+D7*가정!$C$14+E7*가정!$C$18 -> -0.005 | I7: =I6*(1+H7) -> 19.701497 | J7: =I7*(1+G7*가정!$C$19) -> 19.701497 | K7: =I7*가정!$C$36*(1+G7*가정!$C$19*가정!$C$24) -> 9.8507487 | L7: =가정!$C$38+D7*가정!$C$12+E7*가정!$C$17 -> 0.111 | M7: =가정!$C$38+가정!$C$23*(L7-가정!$C$38) -> 0.111 | N7: =N6+K6 -> 29.85025 | O7: =K7+가정!$C$33*M7+N7*L7 -> 58.230127 | P7: =가정!$C$39*(1+D7*가정!$C$13) -> 1.289 | Q7: =1+F7*가정!$C$15 -> 1 | R7: =P7*Q7 -> 1.289 | S7: =O7*R7 -> 75.058633 | T7: =IF(F7=1,가정!$C$16,가정!$C$40) -> 31846 | U7: =S7*T7/10000 -> 239.03172 | V7: =U7/(1-가정!$C$41)*가정!$C$42 -> 251.61234 | W7: =가정!$C$33+N7+K7 -> 445.701 | X7: =X6+J7-K7 -> 655.701 | Y7: =W7+X7 -> 1101.402 | Z7: =O7*P7 -> 75.058633
A8: 5 | B8: 2027 | C8: 5 | D8: =가정!$D$6*MIN(1,MAX(0,(A8-가정!$C$28+1)/가정!$C$30)) -> 0 | E8: =IF(가정!$D$7<30000,1,0)*MIN(1,MAX(0,(A8-가정!$C$29+1)/가정!$C$30)) -> 0 | F8: =IF(가정!$D$7<30000,1,0)*IF(A8>=가정!$C$29,1,0) -> 0 | G8: =가정!$D$8*MIN(1,MAX(0,(A8-가정!$C$31+1)/가정!$C$32)) -> 0 | H8: =가정!$C$37+D8*가정!$C$14+E8*가정!$C$18 -> -0.005 | I8: =I7*(1+H8) -> 19.60299 | J8: =I8*(1+G8*가정!$C$19) -> 19.60299 | K8: =I8*가정!$C$36*(1+G8*가정!$C$19*가정!$C$24) -> 9.801495 | L8: =가정!$C$38+D8*가정!$C$12+E8*가정!$C$17 -> 0.111 | M8: =가정!$C$38+가정!$C$23*(L8-가정!$C$38) -> 0.111 | N8: =N7+K7 -> 39.700999 | O8: =K8+가정!$C$33*M8+N8*L8 -> 59.274306 | P8: =가정!$C$39*(1+D8*가정!$C$13) -> 1.289 | Q8: =1+F8*가정!$C$15 -> 1 | R8: =P8*Q8 -> 1.289 | S8: =O8*R8 -> 76.40458 | T8: =IF(F8=1,가정!$C$16,가정!$C$40) -> 31846 | U8: =S8*T8/10000 -> 243.31803 | V8: =U8/(1-가정!$C$41)*가정!$C$42 -> 256.12424 | W8: =가정!$C$33+N8+K8 -> 455.50249 | X8: =X7+J8-K8 -> 665.50249 | Y8: =W8+X8 -> 1121.005 | Z8: =O8*P8 -> 76.40458
A9: 6 | B9: 2027 | C9: 6 | D9: =가정!$D$6*MIN(1,MAX(0,(A9-가정!$C$28+1)/가정!$C$30)) -> 0.020833333 | E9: =IF(가정!$D$7<30000,1,0)*MIN(1,MAX(0,(A9-가정!$C$29+1)/가정!$C$30)) -> 0 | F9: =IF(가정!$D$7<30000,1,0)*IF(A9>=가정!$C$29,1,0) -> 0 | G9: =가정!$D$8*MIN(1,MAX(0,(A9-가정!$C$31+1)/가정!$C$32)) -> 0 | H9: =가정!$C$37+D9*가정!$C$14+E9*가정!$C$18 -> -0.0049583333 | I9: =I8*(1+H9) -> 19.505792 | J9: =I9*(1+G9*가정!$C$19) -> 19.505792 | K9: =I9*가정!$C$36*(1+G9*가정!$C$19*가정!$C$24) -> 9.7528959 | L9: =가정!$C$38+D9*가정!$C$12+E9*가정!$C$17 -> 0.11139583 | M9: =가정!$C$38+가정!$C$23*(L9-가정!$C$38) -> 0.11139583 | N9: =N8+K8 -> 49.502494 | O9: =K9+가정!$C$33*M9+N9*L9 -> 60.493976 | P9: =가정!$C$39*(1+D9*가정!$C$13) -> 1.2943708 | Q9: =1+F9*가정!$C$15 -> 1 | R9: =P9*Q9 -> 1.2943708 | S9: =O9*R9 -> 78.301638 | T9: =IF(F9=1,가정!$C$16,가정!$C$40) -> 31846 | U9: =S9*T9/10000 -> 249.3594 | V9: =U9/(1-가정!$C$41)*가정!$C$42 -> 262.48357 | W9: =가정!$C$33+N9+K9 -> 465.25539 | X9: =X8+J9-K9 -> 675.25539 | Y9: =W9+X9 -> 1140.5108 | Z9: =O9*P9 -> 78.301638
A10: 7 | B10: 2027 | C10: 7 | D10: =가정!$D$6*MIN(1,MAX(0,(A10-가정!$C$28+1)/가정!$C$30)) -> 0.041666667 | E10: =IF(가정!$D$7<30000,1,0)*MIN(1,MAX(0,(A10-가정!$C$29+1)/가정!$C$30)) -> 0 | F10: =IF(가정!$D$7<30000,1,0)*IF(A10>=가정!$C$29,1,0) -> 0 | G10: =가정!$D$8*MIN(1,MAX(0,(A10-가정!$C$31+1)/가정!$C$32)) -> 0 | H10: =가정!$C$37+D10*가정!$C$14+E10*가정!$C$18 -> -0.0049166667 | I10: =I9*(1+H10) -> 19.409888 | J10: =I10*(1+G10*가정!$C$19) -> 19.409888 | K10: =I10*가정!$C$36*(1+G10*가정!$C$19*가정!$C$24) -> 9.7049442 | L10: =가정!$C$38+D10*가정!$C$12+E10*가정!$C$17 -> 0.11179167 | M10: =가정!$C$38+가정!$C$23*(L10-가정!$C$38) -> 0.11179167 | N10: =N9+K9 -> 59.25539 | O10: =K10+가정!$C$33*M10+N10*L10 -> 61.71662 | P10: =가정!$C$39*(1+D10*가정!$C$13) -> 1.2997417 | Q10: =1+F10*가정!$C$15 -> 1 | R10: =P10*Q10 -> 1.2997417 | S10: =O10*R10 -> 80.215662 | T10: =IF(F10=1,가정!$C$16,가정!$C$40) -> 31846 | U10: =S10*T10/10000 -> 255.4548 | V10: =U10/(1-가정!$C$41)*가정!$C$42 -> 268.89979 | W10: =가정!$C$33+N10+K10 -> 474.96033 | X10: =X9+J10-K10 -> 684.96033 | Y10: =W10+X10 -> 1159.9207 | Z10: =O10*P10 -> 80.215662
A11: 8 | B11: 2027 | C11: 8 | D11: =가정!$D$6*MIN(1,MAX(0,(A11-가정!$C$28+1)/가정!$C$30)) -> 0.0625 | E11: =IF(가정!$D$7<30000,1,0)*MIN(1,MAX(0,(A11-가정!$C$29+1)/가정!$C$30)) -> 0 | F11: =IF(가정!$D$7<30000,1,0)*IF(A11>=가정!$C$29,1,0) -> 0 | G11: =가정!$D$8*MIN(1,MAX(0,(A11-가정!$C$31+1)/가정!$C$32)) -> 0 | H11: =가정!$C$37+D11*가정!$C$14+E11*가정!$C$18 -> -0.004875 | I11: =I10*(1+H11) -> 19.315265 | J11: =I11*(1+G11*가정!$C$19) -> 19.315265 | K11: =I11*가정!$C$36*(1+G11*가정!$C$19*가정!$C$24) -> 9.6576326 | L11: =가정!$C$38+D11*가정!$C$12+E11*가정!$C$17 -> 0.1121875 | M11: =가정!$C$38+가정!$C$23*(L11-가정!$C$38) -> 0.1121875 | N11: =N10+K10 -> 68.960334 | O11: =K11+가정!$C$33*M11+N11*L11 -> 62.942245 | P11: =가정!$C$39*(1+D11*가정!$C$13) -> 1.3051125 | Q11: =1+F11*가정!$C$15 -> 1 | R11: =P11*Q11 -> 1.3051125 | S11: =O11*R11 -> 82.146711 | T11: =IF(F11=1,가정!$C$16,가정!$C$40) -> 31846 | U11: =S11*T11/10000 -> 261.60442 | V11: =U11/(1-가정!$C$41)*가정!$C$42 -> 275.37307 | W11: =가정!$C$33+N11+K11 -> 484.61797 | X11: =X10+J11-K11 -> 694.61797 | Y11: =W11+X11 -> 1179.2359 | Z11: =O11*P11 -> 82.146711
A12: 9 | B12: 2027 | C12: 9 | D12: =가정!$D$6*MIN(1,MAX(0,(A12-가정!$C$28+1)/가정!$C$30)) -> 0.083333333 | E12: =IF(가정!$D$7<30000,1,0)*MIN(1,MAX(0,(A12-가정!$C$29+1)/가정!$C$30)) -> 0 | F12: =IF(가정!$D$7<30000,1,0)*IF(A12>=가정!$C$29,1,0) -> 0 | G12: =가정!$D$8*MIN(1,MAX(0,(A12-가정!$C$31+1)/가정!$C$32)) -> 0 | H12: =가정!$C$37+D12*가정!$C$14+E12*가정!$C$18 -> -0.0048333333 | I12: =I11*(1+H12) -> 19.221908 | J12: =I12*(1+G12*가정!$C$19) -> 19.221908 | K12: =I12*가정!$C$36*(1+G12*가정!$C$19*가정!$C$24) -> 9.610954 | L12: =가정!$C$38+D12*가정!$C$12+E12*가정!$C$17 -> 0.11258333 | M12: =가정!$C$38+가정!$C$23*(L12-가정!$C$38) -> 0.11258333 | N12: =N11+K11 -> 78.617966 | O12: =K12+가정!$C$33*M12+N12*L12 -> 64.17086 | P12: =가정!$C$39*(1+D12*가정!$C$13) -> 1.3104833 | Q12: =1+F12*가정!$C$15 -> 1 | R12: =P12*Q12 -> 1.3104833 | S12: =O12*R12 -> 84.094843 | T12: =IF(F12=1,가정!$C$16,가정!$C$40) -> 31846 | U12: =S12*T12/10000 -> 267.80844 | V12: =U12/(1-가정!$C$41)*가정!$C$42 -> 281.90362 | W12: =가정!$C$33+N12+K12 -> 494.22892 | X12: =X11+J12-K12 -> 704.22892 | Y12: =W12+X12 -> 1198.4578 | Z12: =O12*P12 -> 84.094843
A13: 10 | B13: 2027 | C13: 10 | D13: =가정!$D$6*MIN(1,MAX(0,(A13-가정!$C$28+1)/가정!$C$30)) -> 0.10416667 | E13: =IF(가정!$D$7<30000,1,0)*MIN(1,MAX(0,(A13-가정!$C$29+1)/가정!$C$30)) -> 0 | F13: =IF(가정!$D$7<30000,1,0)*IF(A13>=가정!$C$29,1,0) -> 0 | G13: =가정!$D$8*MIN(1,MAX(0,(A13-가정!$C$31+1)/가정!$C$32)) -> 0 | H13: =가정!$C$37+D13*가정!$C$14+E13*가정!$C$18 -> -0.0047916667 | I13: =I12*(1+H13) -> 19.129803 | J13: =I13*(1+G13*가정!$C$19) -> 19.129803 | K13: =I13*가정!$C$36*(1+G13*가정!$C$19*가정!$C$24) -> 9.5649015 | L13: =가정!$C$38+D13*가정!$C$12+E13*가정!$C$17 -> 0.11297917 | M13: =가정!$C$38+가정!$C$23*(L13-가정!$C$38) -> 0.11297917 | N13: =N12+K12 -> 88.22892 | O13: =K13+가정!$C$33*M13+N13*L13 -> 65.402473 | P13: =가정!$C$39*(1+D13*가정!$C$13) -> 1.3158542 | Q13: =1+F13*가정!$C$15 -> 1 | R13: =P13*Q13 -> 1.3158542 | S13: =O13*R13 -> 86.060117 | T13: =IF(F13=1,가정!$C$16,가정!$C$40) -> 31846 | U13: =S13*T13/10000 -> 274.06705 | V13: =U13/(1-가정!$C$41)*가정!$C$42 -> 288.49163 | W13: =가정!$C$33+N13+K13 -> 503.79382 | X13: =X12+J13-K13 -> 713.79382 | Y13: =W13+X13 -> 1217.5876 | Z13: =O13*P13 -> 86.060117
A14: 11 | B14: 2027 | C14: 11 | D14: =가정!$D$6*MIN(1,MAX(0,(A14-가정!$C$28+1)/가정!$C$30)) -> 0.125 | E14: =IF(가정!$D$7<30000,1,0)*MIN(1,MAX(0,(A14-가정!$C$29+1)/가정!$C$30)) -> 0 | F14: =IF(가정!$D$7<30000,1,0)*IF(A14>=가정!$C$29,1,0) -> 0 | G14: =가정!$D$8*MIN(1,MAX(0,(A14-가정!$C$31+1)/가정!$C$32)) -> 0 | H14: =가정!$C$37+D14*가정!$C$14+E14*가정!$C$18 -> -0.00475 | I14: =I13*(1+H14) -> 19.038937 | J14: =I14*(1+G14*가정!$C$19) -> 19.038937 | K14: =I14*가정!$C$36*(1+G14*가정!$C$19*가정!$C$24) -> 9.5194683 | L14: =가정!$C$38+D14*가정!$C$12+E14*가정!$C$17 -> 0.113375 | M14: =가정!$C$38+가정!$C$23*(L14-가정!$C$38) -> 0.113375 | N14: =N13+K13 -> 97.793822 | O14: =K14+가정!$C$33*M14+N14*L14 -> 66.637093 | P14: =가정!$C$39*(1+D14*가정!$C$13) -> 1.321225 | Q14: =1+F14*가정!$C$15 -> 1 | R14: =P14*Q14 -> 1.321225 | S14: =O14*R14 -> 88.042593 | T14: =IF(F14=1,가정!$C$16,가정!$C$40) -> 31846 | U14: =S14*T14/10000 -> 280.38044 | V14: =U14/(1-가정!$C$41)*가정!$C$42 -> 295.13731 | W14: =가정!$C$33+N14+K14 -> 513.31329 | X14: =X13+J14-K14 -> 723.31329 | Y14: =W14+X14 -> 1236.6266 | Z14: =O14*P14 -> 88.042593
A15: 12 | B15: 2027 | C15: 12 | D15: =가정!$D$6*MIN(1,MAX(0,(A15-가정!$C$28+1)/가정!$C$30)) -> 0.14583333 | E15: =IF(가정!$D$7<30000,1,0)*MIN(1,MAX(0,(A15-가정!$C$29+1)/가정!$C$30)) -> 0 | F15: =IF(가정!$D$7<30000,1,0)*IF(A15>=가정!$C$29,1,0) -> 0 | G15: =가정!$D$8*MIN(1,MAX(0,(A15-가정!$C$31+1)/가정!$C$32)) -> 0 | H15: =가정!$C$37+D15*가정!$C$14+E15*가정!$C$18 -> -0.0047083333 | I15: =I14*(1+H15) -> 18.949295 | J15: =I15*(1+G15*가정!$C$19) -> 18.949295 | K15: =I15*가정!$C$36*(1+G15*가정!$C$19*가정!$C$24) -> 9.4746474 | L15: =가정!$C$38+D15*가정!$C$12+E15*가정!$C$17 -> 0.11377083 | M15: =가정!$C$38+가정!$C$23*(L15-가정!$C$38) -> 0.11377083 | N15: =N14+K14 -> 107.31329 | O15: =K15+가정!$C$33*M15+N15*L15 -> 67.874728 | P15: =가정!$C$39*(1+D15*가정!$C$13) -> 1.3265958 | Q15: =1+F15*가정!$C$15 -> 1 | R15: =P15*Q15 -> 1.3265958 | S15: =O15*R15 -> 90.042332 | T15: =IF(F15=1,가정!$C$16,가정!$C$40) -> 31846 | U15: =S15*T15/10000 -> 286.74881 | V15: =U15/(1-가정!$C$41)*가정!$C$42 -> 301.84085 | W15: =가정!$C$33+N15+K15 -> 522.78794 | X15: =X14+J15-K15 -> 732.78794 | Y15: =W15+X15 -> 1255.5759 | Z15: =O15*P15 -> 90.042332
A16: 13 | B16: 2028 | C16: 1 | D16: =가정!$D$6*MIN(1,MAX(0,(A16-가정!$C$28+1)/가정!$C$30)) -> 0.16666667 | E16: =IF(가정!$D$7<30000,1,0)*MIN(1,MAX(0,(A16-가정!$C$29+1)/가정!$C$30)) -> 0 | F16: =IF(가정!$D$7<30000,1,0)*IF(A16>=가정!$C$29,1,0) -> 0 | G16: =가정!$D$8*MIN(1,MAX(0,(A16-가정!$C$31+1)/가정!$C$32)) -> 0 | H16: =가정!$C$37+D16*가정!$C$14+E16*가정!$C$18 -> -0.0046666667 | I16: =I15*(1+H16) -> 18.860865 | J16: =I16*(1+G16*가정!$C$19) -> 18.860865 | K16: =I16*가정!$C$36*(1+G16*가정!$C$19*가정!$C$24) -> 9.4304324 | L16: =가정!$C$38+D16*가정!$C$12+E16*가정!$C$17 -> 0.11416667 | M16: =가정!$C$38+가정!$C$23*(L16-가정!$C$38) -> 0.11416667 | N16: =N15+K15 -> 116.78794 | O16: =K16+가정!$C$33*M16+N16*L16 -> 69.115389 | P16: =가정!$C$39*(1+D16*가정!$C$13) -> 1.3319667 | Q16: =1+F16*가정!$C$15 -> 1 | R16: =P16*Q16 -> 1.3319667 | S16: =O16*R16 -> 92.059394 | T16: =IF(F16=1,가정!$C$16,가정!$C$40) -> 31846 | U16: =S16*T16/10000 -> 293.17235 | V16: =U16/(1-가정!$C$41)*가정!$C$42 -> 308.60247 | W16: =가정!$C$33+N16+K16 -> 532.21837 | X16: =X15+J16-K16 -> 742.21837 | Y16: =W16+X16 -> 1274.4367 | Z16: =O16*P16 -> 92.059394
... A63: 60 | B63: 2031 | C63: 12 | D63: =가정!$D$6*MIN(1,MAX(0,(A63-가정!$C$28+1)/가정!$C$30)) -> 1 | E63: =IF(가정!$D$7<30000,1,0)*MIN(1,MAX(0,(A63-가정!$C$29+1)/가정!$C$30)) -> 0 | F63: =IF(가정!$D$7<30000,1,0)*IF(A63>=가정!$C$29,1,0) -> 0 | G63: =가정!$D$8*MIN(1,MAX(0,(A63-가정!$C$31+1)/가정!$C$32)) -> 0 | H63: =가정!$C$37+D63*가정!$C$14+E63*가정!$C$18 -> -0.003 | I63: =I62*(1+H63) -> 15.851458 | J63: =I63*(1+G63*가정!$C$19) -> 15.851458 | K63: =I63*가정!$C$36*(1+G63*가정!$C$19*가정!$C$24) -> 7.9257288 | L63: =가정!$C$38+D63*가정!$C$12+E63*가정!$C$17 -> 0.13 | M63: =가정!$C$38+가정!$C$23*(L63-가정!$C$38) -> 0.13 | N63: =N62+K62 -> 521.47805 | O63: =K63+가정!$C$33*M63+N63*L63 -> 128.49788 | P63: =가정!$C$39*(1+D63*가정!$C$13) -> 1.5468 | Q63: =1+F63*가정!$C$15 -> 1 | R63: =P63*Q63 -> 1.5468 | S63: =O63*R63 -> 198.76051 | T63: =IF(F63=1,가정!$C$16,가정!$C$40) -> 31846 | U63: =S63*T63/10000 -> 632.97273 | V63: =U63/(1-가정!$C$41)*가정!$C$42 -> 666.28709 | W63: =가정!$C$33+N63+K63 -> 935.40378 | X63: =X62+J63-K63 -> 1145.4038 | Y63: =W63+X63 -> 2080.8076 | Z63: =O63*P63 -> 198.76051

Sheet S3_익일무배
A1: S3 익일배송 + 무배 2.5만
A2: 레버 값은 가정 시트 A에서, 나머지는 B~D에서 가져옵니다. 이 시트는 수정하지 마십시오.
A3: 월차 | B3: 연도 | C3: 월 | D3: 익일 진행도 | E3: 무배 진행도 | F3: 무배 적용 | G3: 회원확대 진행도 | H3: 가입 증감률 | I3: 기본 가입 추세 (만명) | J3: 월 가입 (만명) | K3: 신규 구매고객 (만명) | L3: 잔존율 신규 코호트 | M3: 잔존율 기존 고객 | N3: 2027~ 누적 (월초, 만명) | O3: 활동 구매고객 (만명) | P3: 익일 효과 빈도 | Q3: 즉시 주문 배수 | R3: 구매빈도 (건/월) | S3: 구매건수 (만건) | T3: 객단가 (원) | U3: 택배매출 (억원) | V3: 총매출 (억원) | W3: 누적 구매고객 (만명) | X3: 미전환 회원 (만명) | Y3: 회원수 (만명) | Z3: 활동×익일빈도 (보조)
A4: 1 | B4: 2027 | C4: 1 | D4: =가정!$E$6*MIN(1,MAX(0,(A4-가정!$C$28+1)/가정!$C$30)) -> 0 | E4: =IF(가정!$E$7<30000,1,0)*MIN(1,MAX(0,(A4-가정!$C$29+1)/가정!$C$30)) -> 0 | F4: =IF(가정!$E$7<30000,1,0)*IF(A4>=가정!$C$29,1,0) -> 0 | G4: =가정!$E$8*MIN(1,MAX(0,(A4-가정!$C$31+1)/가정!$C$32)) -> 0 | H4: =가정!$C$37+D4*가정!$C$14+E4*가정!$C$18 -> -0.005 | I4: =가정!$C$35 -> 20 | J4: =I4*(1+G4*가정!$C$19) -> 20 | K4: =I4*가정!$C$36*(1+G4*가정!$C$19*가정!$C$24) -> 10 | L4: =가정!$C$38+D4*가정!$C$12+E4*가정!$C$17 -> 0.111 | M4: =가정!$C$38+가정!$C$23*(L4-가정!$C$38) -> 0.111 | N4: =0 -> 0 | O4: =K4+가정!$C$33*M4+N4*L4 -> 55.066 | P4: =가정!$C$39*(1+D4*가정!$C$13) -> 1.289 | Q4: =1+F4*가정!$C$15 -> 1 | R4: =P4*Q4 -> 1.289 | S4: =O4*R4 -> 70.980074 | T4: =IF(F4=1,가정!$C$16,가정!$C$40) -> 31846 | U4: =S4*T4/10000 -> 226.04314 | V4: =U4/(1-가정!$C$41)*가정!$C$42 -> 237.94015 | W4: =가정!$C$33+N4+K4 -> 416 | X4: =(가정!$C$34-가정!$C$33)+J4-K4 -> 626 | Y4: =W4+X4 -> 1042 | Z4: =O4*P4 -> 70.980074
A5: 2 | B5: 2027 | C5: 2 | D5: =가정!$E$6*MIN(1,MAX(0,(A5-가정!$C$28+1)/가정!$C$30)) -> 0 | E5: =IF(가정!$E$7<30000,1,0)*MIN(1,MAX(0,(A5-가정!$C$29+1)/가정!$C$30)) -> 0 | F5: =IF(가정!$E$7<30000,1,0)*IF(A5>=가정!$C$29,1,0) -> 0 | G5: =가정!$E$8*MIN(1,MAX(0,(A5-가정!$C$31+1)/가정!$C$32)) -> 0 | H5: =가정!$C$37+D5*가정!$C$14+E5*가정!$C$18 -> -0.005 | I5: =I4*(1+H5) -> 19.9 | J5: =I5*(1+G5*가정!$C$19) -> 19.9 | K5: =I5*가정!$C$36*(1+G5*가정!$C$19*가정!$C$24) -> 9.95 | L5: =가정!$C$38+D5*가정!$C$12+E5*가정!$C$17 -> 0.111 | M5: =가정!$C$38+가정!$C$23*(L5-가정!$C$38) -> 0.111 | N5: =N4+K4 -> 10 | O5: =K5+가정!$C$33*M5+N5*L5 -> 56.126 | P5: =가정!$C$39*(1+D5*가정!$C$13) -> 1.289 | Q5: =1+F5*가정!$C$15 -> 1 | R5: =P5*Q5 -> 1.289 | S5: =O5*R5 -> 72.346414 | T5: =IF(F5=1,가정!$C$16,가정!$C$40) -> 31846 | U5: =S5*T5/10000 -> 230.39439 | V5: =U5/(1-가정!$C$41)*가정!$C$42 -> 242.52041 | W5: =가정!$C$33+N5+K5 -> 425.95 | X5: =X4+J5-K5 -> 635.95 | Y5: =W5+X5 -> 1061.9 | Z5: =O5*P5 -> 72.346414
A6: 3 | B6: 2027 | C6: 3 | D6: =가정!$E$6*MIN(1,MAX(0,(A6-가정!$C$28+1)/가정!$C$30)) -> 0 | E6: =IF(가정!$E$7<30000,1,0)*MIN(1,MAX(0,(A6-가정!$C$29+1)/가정!$C$30)) -> 0 | F6: =IF(가정!$E$7<30000,1,0)*IF(A6>=가정!$C$29,1,0) -> 0 | G6: =가정!$E$8*MIN(1,MAX(0,(A6-가정!$C$31+1)/가정!$C$32)) -> 0 | H6: =가정!$C$37+D6*가정!$C$14+E6*가정!$C$18 -> -0.005 | I6: =I5*(1+H6) -> 19.8005 | J6: =I6*(1+G6*가정!$C$19) -> 19.8005 | K6: =I6*가정!$C$36*(1+G6*가정!$C$19*가정!$C$24) -> 9.90025 | L6: =가정!$C$38+D6*가정!$C$12+E6*가정!$C$17 -> 0.111 | M6: =가정!$C$38+가정!$C$23*(L6-가정!$C$38) -> 0.111 | N6: =N5+K5 -> 19.95 | O6: =K6+가정!$C$33*M6+N6*L6 -> 57.1807 | P6: =가정!$C$39*(1+D6*가정!$C$13) -> 1.289 | Q6: =1+F6*가정!$C$15 -> 1 | R6: =P6*Q6 -> 1.289 | S6: =O6*R6 -> 73.705922 | T6: =IF(F6=1,가정!$C$16,가정!$C$40) -> 31846 | U6: =S6*T6/10000 -> 234.72388 | V6: =U6/(1-가정!$C$41)*가정!$C$42 -> 247.07777 | W6: =가정!$C$33+N6+K6 -> 435.85025 | X6: =X5+J6-K6 -> 645.85025 | Y6: =W6+X6 -> 1081.7005 | Z6: =O6*P6 -> 73.705922
A7: 4 | B7: 2027 | C7: 4 | D7: =가정!$E$6*MIN(1,MAX(0,(A7-가정!$C$28+1)/가정!$C$30)) -> 0 | E7: =IF(가정!$E$7<30000,1,0)*MIN(1,MAX(0,(A7-가정!$C$29+1)/가정!$C$30)) -> 0 | F7: =IF(가정!$E$7<30000,1,0)*IF(A7>=가정!$C$29,1,0) -> 0 | G7: =가정!$E$8*MIN(1,MAX(0,(A7-가정!$C$31+1)/가정!$C$32)) -> 0 | H7: =가정!$C$37+D7*가정!$C$14+E7*가정!$C$18 -> -0.005 | I7: =I6*(1+H7) -> 19.701497 | J7: =I7*(1+G7*가정!$C$19) -> 19.701497 | K7: =I7*가정!$C$36*(1+G7*가정!$C$19*가정!$C$24) -> 9.8507487 | L7: =가정!$C$38+D7*가정!$C$12+E7*가정!$C$17 -> 0.111 | M7: =가정!$C$38+가정!$C$23*(L7-가정!$C$38) -> 0.111 | N7: =N6+K6 -> 29.85025 | O7: =K7+가정!$C$33*M7+N7*L7 -> 58.230127 | P7: =가정!$C$39*(1+D7*가정!$C$13) -> 1.289 | Q7: =1+F7*가정!$C$15 -> 1 | R7: =P7*Q7 -> 1.289 | S7: =O7*R7 -> 75.058633 | T7: =IF(F7=1,가정!$C$16,가정!$C$40) -> 31846 | U7: =S7*T7/10000 -> 239.03172 | V7: =U7/(1-가정!$C$41)*가정!$C$42 -> 251.61234 | W7: =가정!$C$33+N7+K7 -> 445.701 | X7: =X6+J7-K7 -> 655.701 | Y7: =W7+X7 -> 1101.402 | Z7: =O7*P7 -> 75.058633
A8: 5 | B8: 2027 | C8: 5 | D8: =가정!$E$6*MIN(1,MAX(0,(A8-가정!$C$28+1)/가정!$C$30)) -> 0 | E8: =IF(가정!$E$7<30000,1,0)*MIN(1,MAX(0,(A8-가정!$C$29+1)/가정!$C$30)) -> 0 | F8: =IF(가정!$E$7<30000,1,0)*IF(A8>=가정!$C$29,1,0) -> 0 | G8: =가정!$E$8*MIN(1,MAX(0,(A8-가정!$C$31+1)/가정!$C$32)) -> 0 | H8: =가정!$C$37+D8*가정!$C$14+E8*가정!$C$18 -> -0.005 | I8: =I7*(1+H8) -> 19.60299 | J8: =I8*(1+G8*가정!$C$19) -> 19.60299 | K8: =I8*가정!$C$36*(1+G8*가정!$C$19*가정!$C$24) -> 9.801495 | L8: =가정!$C$38+D8*가정!$C$12+E8*가정!$C$17 -> 0.111 | M8: =가정!$C$38+가정!$C$23*(L8-가정!$C$38) -> 0.111 | N8: =N7+K7 -> 39.700999 | O8: =K8+가정!$C$33*M8+N8*L8 -> 59.274306 | P8: =가정!$C$39*(1+D8*가정!$C$13) -> 1.289 | Q8: =1+F8*가정!$C$15 -> 1 | R8: =P8*Q8 -> 1.289 | S8: =O8*R8 -> 76.40458 | T8: =IF(F8=1,가정!$C$16,가정!$C$40) -> 31846 | U8: =S8*T8/10000 -> 243.31803 | V8: =U8/(1-가정!$C$41)*가정!$C$42 -> 256.12424 | W8: =가정!$C$33+N8+K8 -> 455.50249 | X8: =X7+J8-K8 -> 665.50249 | Y8: =W8+X8 -> 1121.005 | Z8: =O8*P8 -> 76.40458
A9: 6 | B9: 2027 | C9: 6 | D9: =가정!$E$6*MIN(1,MAX(0,(A9-가정!$C$28+1)/가정!$C$30)) -> 0.020833333 | E9: =IF(가정!$E$7<30000,1,0)*MIN(1,MAX(0,(A9-가정!$C$29+1)/가정!$C$30)) -> 0 | F9: =IF(가정!$E$7<30000,1,0)*IF(A9>=가정!$C$29,1,0) -> 0 | G9: =가정!$E$8*MIN(1,MAX(0,(A9-가정!$C$31+1)/가정!$C$32)) -> 0 | H9: =가정!$C$37+D9*가정!$C$14+E9*가정!$C$18 -> -0.0049583333 | I9: =I8*(1+H9) -> 19.505792 | J9: =I9*(1+G9*가정!$C$19) -> 19.505792 | K9: =I9*가정!$C$36*(1+G9*가정!$C$19*가정!$C$24) -> 9.7528959 | L9: =가정!$C$38+D9*가정!$C$12+E9*가정!$C$17 -> 0.11139583 | M9: =가정!$C$38+가정!$C$23*(L9-가정!$C$38) -> 0.11139583 | N9: =N8+K8 -> 49.502494 | O9: =K9+가정!$C$33*M9+N9*L9 -> 60.493976 | P9: =가정!$C$39*(1+D9*가정!$C$13) -> 1.2943708 | Q9: =1+F9*가정!$C$15 -> 1 | R9: =P9*Q9 -> 1.2943708 | S9: =O9*R9 -> 78.301638 | T9: =IF(F9=1,가정!$C$16,가정!$C$40) -> 31846 | U9: =S9*T9/10000 -> 249.3594 | V9: =U9/(1-가정!$C$41)*가정!$C$42 -> 262.48357 | W9: =가정!$C$33+N9+K9 -> 465.25539 | X9: =X8+J9-K9 -> 675.25539 | Y9: =W9+X9 -> 1140.5108 | Z9: =O9*P9 -> 78.301638
A10: 7 | B10: 2027 | C10: 7 | D10: =가정!$E$6*MIN(1,MAX(0,(A10-가정!$C$28+1)/가정!$C$30)) -> 0.041666667 | E10: =IF(가정!$E$7<30000,1,0)*MIN(1,MAX(0,(A10-가정!$C$29+1)/가정!$C$30)) -> 0.020833333 | F10: =IF(가정!$E$7<30000,1,0)*IF(A10>=가정!$C$29,1,0) -> 1 | G10: =가정!$E$8*MIN(1,MAX(0,(A10-가정!$C$31+1)/가정!$C$32)) -> 0 | H10: =가정!$C$37+D10*가정!$C$14+E10*가정!$C$18 -> -0.004875 | I10: =I9*(1+H10) -> 19.410701 | J10: =I10*(1+G10*가정!$C$19) -> 19.410701 | K10: =I10*가정!$C$36*(1+G10*가정!$C$19*가정!$C$24) -> 9.7053506 | L10: =가정!$C$38+D10*가정!$C$12+E10*가정!$C$17 -> 0.11220833 | M10: =가정!$C$38+가정!$C$23*(L10-가정!$C$38) -> 0.11220833 | N10: =N9+K9 -> 59.25539 | O10: =K10+가정!$C$33*M10+N10*L10 -> 61.910882 | P10: =가정!$C$39*(1+D10*가정!$C$13) -> 1.2997417 | Q10: =1+F10*가정!$C$15 -> 1.086 | R10: =P10*Q10 -> 1.4115194 | S10: =O10*R10 -> 87.388415 | T10: =IF(F10=1,가정!$C$16,가정!$C$40) -> 29800 | U10: =S10*T10/10000 -> 260.41748 | V10: =U10/(1-가정!$C$41)*가정!$C$42 -> 274.12366 | W10: =가정!$C$33+N10+K10 -> 474.96074 | X10: =X9+J10-K10 -> 684.96074 | Y10: =W10+X10 -> 1159.9215 | Z10: =O10*P10 -> 80.468153
A11: 8 | B11: 2027 | C11: 8 | D11: =가정!$E$6*MIN(1,MAX(0,(A11-가정!$C$28+1)/가정!$C$30)) -> 0.0625 | E11: =IF(가정!$E$7<30000,1,0)*MIN(1,MAX(0,(A11-가정!$C$29+1)/가정!$C$30)) -> 0.041666667 | F11: =IF(가정!$E$7<30000,1,0)*IF(A11>=가정!$C$29,1,0) -> 1 | G11: =가정!$E$8*MIN(1,MAX(0,(A11-가정!$C$31+1)/가정!$C$32)) -> 0 | H11: =가정!$C$37+D11*가정!$C$14+E11*가정!$C$18 -> -0.0047916667 | I11: =I10*(1+H11) -> 19.317692 | J11: =I11*(1+G11*가정!$C$19) -> 19.317692 | K11: =I11*가정!$C$36*(1+G11*가정!$C$19*가정!$C$24) -> 9.6588458 | L11: =가정!$C$38+D11*가정!$C$12+E11*가정!$C$17 -> 0.11302083 | M11: =가정!$C$38+가정!$C$23*(L11-가정!$C$38) -> 0.11302083 | N11: =N10+K10 -> 68.96074 | O11: =K11+가정!$C$33*M11+N11*L11 -> 63.339304 | P11: =가정!$C$39*(1+D11*가정!$C$13) -> 1.3051125 | Q11: =1+F11*가정!$C$15 -> 1.086 | R11: =P11*Q11 -> 1.4173522 | S11: =O11*R11 -> 89.774101 | T11: =IF(F11=1,가정!$C$16,가정!$C$40) -> 29800 | U11: =S11*T11/10000 -> 267.52682 | V11: =U11/(1-가정!$C$41)*가정!$C$42 -> 281.60718 | W11: =가정!$C$33+N11+K11 -> 484.61959 | X11: =X10+J11-K11 -> 694.61959 | Y11: =W11+X11 -> 1179.2392 | Z11: =O11*P11 -> 82.664918
A12: 9 | B12: 2027 | C12: 9 | D12: =가정!$E$6*MIN(1,MAX(0,(A12-가정!$C$28+1)/가정!$C$30)) -> 0.083333333 | E12: =IF(가정!$E$7<30000,1,0)*MIN(1,MAX(0,(A12-가정!$C$29+1)/가정!$C$30)) -> 0.0625 | F12: =IF(가정!$E$7<30000,1,0)*IF(A12>=가정!$C$29,1,0) -> 1 | G12: =가정!$E$8*MIN(1,MAX(0,(A12-가정!$C$31+1)/가정!$C$32)) -> 0 | H12: =가정!$C$37+D12*가정!$C$14+E12*가정!$C$18 -> -0.0047083333 | I12: =I11*(1+H12) -> 19.226737 | J12: =I12*(1+G12*가정!$C$19) -> 19.226737 | K12: =I12*가정!$C$36*(1+G12*가정!$C$19*가정!$C$24) -> 9.6133687 | L12: =가정!$C$38+D12*가정!$C$12+E12*가정!$C$17 -> 0.11383333 | M12: =가정!$C$38+가정!$C$23*(L12-가정!$C$38) -> 0.11383333 | N12: =N11+K11 -> 78.619586 | O12: =K12+가정!$C$33*M12+N12*L12 -> 64.779232 | P12: =가정!$C$39*(1+D12*가정!$C$13) -> 1.3104833 | Q12: =1+F12*가정!$C$15 -> 1.086 | R12: =P12*Q12 -> 1.4231849 | S12: =O12*R12 -> 92.192824 | T12: =IF(F12=1,가정!$C$16,가정!$C$40) -> 29800 | U12: =S12*T12/10000 -> 274.73462 | V12: =U12/(1-가정!$C$41)*가정!$C$42 -> 289.19433 | W12: =가정!$C$33+N12+K12 -> 494.23295 | X12: =X11+J12-K12 -> 704.23295 | Y12: =W12+X12 -> 1198.4659 | Z12: =O12*P12 -> 84.892103
A13: 10 | B13: 2027 | C13: 10 | D13: =가정!$E$6*MIN(1,MAX(0,(A13-가정!$C$28+1)/가정!$C$30)) -> 0.10416667 | E13: =IF(가정!$E$7<30000,1,0)*MIN(1,MAX(0,(A13-가정!$C$29+1)/가정!$C$30)) -> 0.083333333 | F13: =IF(가정!$E$7<30000,1,0)*IF(A13>=가정!$C$29,1,0) -> 1 | G13: =가정!$E$8*MIN(1,MAX(0,(A13-가정!$C$31+1)/가정!$C$32)) -> 0 | H13: =가정!$C$37+D13*가정!$C$14+E13*가정!$C$18 -> -0.004625 | I13: =I12*(1+H13) -> 19.137814 | J13: =I13*(1+G13*가정!$C$19) -> 19.137814 | K13: =I13*가정!$C$36*(1+G13*가정!$C$19*가정!$C$24) -> 9.5689069 | L13: =가정!$C$38+D13*가정!$C$12+E13*가정!$C$17 -> 0.11464583 | M13: =가정!$C$38+가정!$C$23*(L13-가정!$C$38) -> 0.11464583 | N13: =N12+K12 -> 88.232955 | O13: =K13+가정!$C$33*M13+N13*L13 -> 66.230656 | P13: =가정!$C$39*(1+D13*가정!$C$13) -> 1.3158542 | Q13: =1+F13*가정!$C$15 -> 1.086 | R13: =P13*Q13 -> 1.4290176 | S13: =O13*R13 -> 94.644774 | T13: =IF(F13=1,가정!$C$16,가정!$C$40) -> 29800 | U13: =S13*T13/10000 -> 282.04143 | V13: =U13/(1-가정!$C$41)*가정!$C$42 -> 296.88571 | W13: =가정!$C$33+N13+K13 -> 503.80186 | X13: =X12+J13-K13 -> 713.80186 | Y13: =W13+X13 -> 1217.6037 | Z13: =O13*P13 -> 87.149884
A14: 11 | B14: 2027 | C14: 11 | D14: =가정!$E$6*MIN(1,MAX(0,(A14-가정!$C$28+1)/가정!$C$30)) -> 0.125 | E14: =IF(가정!$E$7<30000,1,0)*MIN(1,MAX(0,(A14-가정!$C$29+1)/가정!$C$30)) -> 0.10416667 | F14: =IF(가정!$E$7<30000,1,0)*IF(A14>=가정!$C$29,1,0) -> 1 | G14: =가정!$E$8*MIN(1,MAX(0,(A14-가정!$C$31+1)/가정!$C$32)) -> 0 | H14: =가정!$C$37+D14*가정!$C$14+E14*가정!$C$18 -> -0.0045416667 | I14: =I13*(1+H14) -> 19.050896 | J14: =I14*(1+G14*가정!$C$19) -> 19.050896 | K14: =I14*가정!$C$36*(1+G14*가정!$C$19*가정!$C$24) -> 9.5254481 | L14: =가정!$C$38+D14*가정!$C$12+E14*가정!$C$17 -> 0.11545833 | M14: =가정!$C$38+가정!$C$23*(L14-가정!$C$38) -> 0.11545833 | N14: =N13+K13 -> 97.801862 | O14: =K14+가정!$C$33*M14+N14*L14 -> 67.693571 | P14: =가정!$C$39*(1+D14*가정!$C$13) -> 1.321225 | Q14: =1+F14*가정!$C$15 -> 1.086 | R14: =P14*Q14 -> 1.4348504 | S14: =O14*R14 -> 97.130145 | T14: =IF(F14=1,가정!$C$16,가정!$C$40) -> 29800 | U14: =S14*T14/10000 -> 289.44783 | V14: =U14/(1-가정!$C$41)*가정!$C$42 -> 304.68193 | W14: =가정!$C$33+N14+K14 -> 513.32731 | X14: =X13+J14-K14 -> 723.32731 | Y14: =W14+X14 -> 1236.6546 | Z14: =O14*P14 -> 89.438439
A15: 12 | B15: 2027 | C15: 12 | D15: =가정!$E$6*MIN(1,MAX(0,(A15-가정!$C$28+1)/가정!$C$30)) -> 0.14583333 | E15: =IF(가정!$E$7<30000,1,0)*MIN(1,MAX(0,(A15-가정!$C$29+1)/가정!$C$30)) -> 0.125 | F15: =IF(가정!$E$7<30000,1,0)*IF(A15>=가정!$C$29,1,0) -> 1 | G15: =가정!$E$8*MIN(1,MAX(0,(A15-가정!$C$31+1)/가정!$C$32)) -> 0 | H15: =가정!$C$37+D15*가정!$C$14+E15*가정!$C$18 -> -0.0044583333 | I15: =I14*(1+H15) -> 18.965961 | J15: =I15*(1+G15*가정!$C$19) -> 18.965961 | K15: =I15*가정!$C$36*(1+G15*가정!$C$19*가정!$C$24) -> 9.4829805 | L15: =가정!$C$38+D15*가정!$C$12+E15*가정!$C$17 -> 0.11627083 | M15: =가정!$C$38+가정!$C$23*(L15-가정!$C$38) -> 0.11627083 | N15: =N14+K14 -> 107.32731 | O15: =K15+가정!$C$33*M15+N15*L15 -> 69.167975 | P15: =가정!$C$39*(1+D15*가정!$C$13) -> 1.3265958 | Q15: =1+F15*가정!$C$15 -> 1.086 | R15: =P15*Q15 -> 1.4406831 | S15: =O15*R15 -> 99.64913 | T15: =IF(F15=1,가정!$C$16,가정!$C$40) -> 29800 | U15: =S15*T15/10000 -> 296.95441 | V15: =U15/(1-가정!$C$41)*가정!$C$42 -> 312.58359 | W15: =가정!$C$33+N15+K15 -> 522.81029 | X15: =X14+J15-K15 -> 732.81029 | Y15: =W15+X15 -> 1255.6206 | Z15: =O15*P15 -> 91.757947
A16: 13 | B16: 2028 | C16: 1 | D16: =가정!$E$6*MIN(1,MAX(0,(A16-가정!$C$28+1)/가정!$C$30)) -> 0.16666667 | E16: =IF(가정!$E$7<30000,1,0)*MIN(1,MAX(0,(A16-가정!$C$29+1)/가정!$C$30)) -> 0.14583333 | F16: =IF(가정!$E$7<30000,1,0)*IF(A16>=가정!$C$29,1,0) -> 1 | G16: =가정!$E$8*MIN(1,MAX(0,(A16-가정!$C$31+1)/가정!$C$32)) -> 0 | H16: =가정!$C$37+D16*가정!$C$14+E16*가정!$C$18 -> -0.004375 | I16: =I15*(1+H16) -> 18.882985 | J16: =I16*(1+G16*가정!$C$19) -> 18.882985 | K16: =I16*가정!$C$36*(1+G16*가정!$C$19*가정!$C$24) -> 9.4414924 | L16: =가정!$C$38+D16*가정!$C$12+E16*가정!$C$17 -> 0.11708333 | M16: =가정!$C$38+가정!$C$23*(L16-가정!$C$38) -> 0.11708333 | N16: =N15+K15 -> 116.81029 | O16: =K16+가정!$C$33*M16+N16*L16 -> 70.653864 | P16: =가정!$C$39*(1+D16*가정!$C$13) -> 1.3319667 | Q16: =1+F16*가정!$C$15 -> 1.086 | R16: =P16*Q16 -> 1.4465158 | S16: =O16*R16 -> 102.20193 | T16: =IF(F16=1,가정!$C$16,가정!$C$40) -> 29800 | U16: =S16*T16/10000 -> 304.56175 | V16: =U16/(1-가정!$C$41)*가정!$C$42 -> 320.59132 | W16: =가정!$C$33+N16+K16 -> 532.25178 | X16: =X15+J16-K16 -> 742.25178 | Y16: =W16+X16 -> 1274.5036 | Z16: =O16*P16 -> 94.108592
... A63: 60 | B63: 2031 | C63: 12 | D63: =가정!$E$6*MIN(1,MAX(0,(A63-가정!$C$28+1)/가정!$C$30)) -> 1 | E63: =IF(가정!$E$7<30000,1,0)*MIN(1,MAX(0,(A63-가정!$C$29+1)/가정!$C$30)) -> 1 | F63: =IF(가정!$E$7<30000,1,0)*IF(A63>=가정!$C$29,1,0) -> 1 | G63: =가정!$E$8*MIN(1,MAX(0,(A63-가정!$C$31+1)/가정!$C$32)) -> 0 | H63: =가정!$C$37+D63*가정!$C$14+E63*가정!$C$18 -> -0.001 | I63: =I62*(1+H63) -> 16.851337 | J63: =I63*(1+G63*가정!$C$19) -> 16.851337 | K63: =I63*가정!$C$36*(1+G63*가정!$C$19*가정!$C$24) -> 8.4256684 | L63: =가정!$C$38+D63*가정!$C$12+E63*가정!$C$17 -> 0.15 | M63: =가정!$C$38+가정!$C$23*(L63-가정!$C$38) -> 0.15 | N63: =N62+K62 -> 530.73135 | O63: =K63+가정!$C$33*M63+N63*L63 -> 148.93537 | P63: =가정!$C$39*(1+D63*가정!$C$13) -> 1.5468 | Q63: =1+F63*가정!$C$15 -> 1.086 | R63: =P63*Q63 -> 1.6798248 | S63: =O63*R63 -> 250.18533 | T63: =IF(F63=1,가정!$C$16,가정!$C$40) -> 29800 | U63: =S63*T63/10000 -> 745.55229 | V63: =U63/(1-가정!$C$41)*가정!$C$42 -> 784.79188 | W63: =가정!$C$33+N63+K63 -> 945.15702 | X63: =X62+J63-K63 -> 1155.157 | Y63: =W63+X63 -> 2100.314 | Z63: =O63*P63 -> 230.37323

Sheet S4_익일무배회원
A1: S4 익일 + 무배 + 회원 확대
A2: 레버 값은 가정 시트 A에서, 나머지는 B~D에서 가져옵니다. 이 시트는 수정하지 마십시오.
A3: 월차 | B3: 연도 | C3: 월 | D3: 익일 진행도 | E3: 무배 진행도 | F3: 무배 적용 | G3: 회원확대 진행도 | H3: 가입 증감률 | I3: 기본 가입 추세 (만명) | J3: 월 가입 (만명) | K3: 신규 구매고객 (만명) | L3: 잔존율 신규 코호트 | M3: 잔존율 기존 고객 | N3: 2027~ 누적 (월초, 만명) | O3: 활동 구매고객 (만명) | P3: 익일 효과 빈도 | Q3: 즉시 주문 배수 | R3: 구매빈도 (건/월) | S3: 구매건수 (만건) | T3: 객단가 (원) | U3: 택배매출 (억원) | V3: 총매출 (억원) | W3: 누적 구매고객 (만명) | X3: 미전환 회원 (만명) | Y3: 회원수 (만명) | Z3: 활동×익일빈도 (보조)
A4: 1 | B4: 2027 | C4: 1 | D4: =가정!$F$6*MIN(1,MAX(0,(A4-가정!$C$28+1)/가정!$C$30)) -> 0 | E4: =IF(가정!$F$7<30000,1,0)*MIN(1,MAX(0,(A4-가정!$C$29+1)/가정!$C$30)) -> 0 | F4: =IF(가정!$F$7<30000,1,0)*IF(A4>=가정!$C$29,1,0) -> 0 | G4: =가정!$F$8*MIN(1,MAX(0,(A4-가정!$C$31+1)/가정!$C$32)) -> 0 | H4: =가정!$C$37+D4*가정!$C$14+E4*가정!$C$18 -> -0.005 | I4: =가정!$C$35 -> 20 | J4: =I4*(1+G4*가정!$C$19) -> 20 | K4: =I4*가정!$C$36*(1+G4*가정!$C$19*가정!$C$24) -> 10 | L4: =가정!$C$38+D4*가정!$C$12+E4*가정!$C$17 -> 0.111 | M4: =가정!$C$38+가정!$C$23*(L4-가정!$C$38) -> 0.111 | N4: =0 -> 0 | O4: =K4+가정!$C$33*M4+N4*L4 -> 55.066 | P4: =가정!$C$39*(1+D4*가정!$C$13) -> 1.289 | Q4: =1+F4*가정!$C$15 -> 1 | R4: =P4*Q4 -> 1.289 | S4: =O4*R4 -> 70.980074 | T4: =IF(F4=1,가정!$C$16,가정!$C$40) -> 31846 | U4: =S4*T4/10000 -> 226.04314 | V4: =U4/(1-가정!$C$41)*가정!$C$42 -> 237.94015 | W4: =가정!$C$33+N4+K4 -> 416 | X4: =(가정!$C$34-가정!$C$33)+J4-K4 -> 626 | Y4: =W4+X4 -> 1042 | Z4: =O4*P4 -> 70.980074
A5: 2 | B5: 2027 | C5: 2 | D5: =가정!$F$6*MIN(1,MAX(0,(A5-가정!$C$28+1)/가정!$C$30)) -> 0 | E5: =IF(가정!$F$7<30000,1,0)*MIN(1,MAX(0,(A5-가정!$C$29+1)/가정!$C$30)) -> 0 | F5: =IF(가정!$F$7<30000,1,0)*IF(A5>=가정!$C$29,1,0) -> 0 | G5: =가정!$F$8*MIN(1,MAX(0,(A5-가정!$C$31+1)/가정!$C$32)) -> 0 | H5: =가정!$C$37+D5*가정!$C$14+E5*가정!$C$18 -> -0.005 | I5: =I4*(1+H5) -> 19.9 | J5: =I5*(1+G5*가정!$C$19) -> 19.9 | K5: =I5*가정!$C$36*(1+G5*가정!$C$19*가정!$C$24) -> 9.95 | L5: =가정!$C$38+D5*가정!$C$12+E5*가정!$C$17 -> 0.111 | M5: =가정!$C$38+가정!$C$23*(L5-가정!$C$38) -> 0.111 | N5: =N4+K4 -> 10 | O5: =K5+가정!$C$33*M5+N5*L5 -> 56.126 | P5: =가정!$C$39*(1+D5*가정!$C$13) -> 1.289 | Q5: =1+F5*가정!$C$15 -> 1 | R5: =P5*Q5 -> 1.289 | S5: =O5*R5 -> 72.346414 | T5: =IF(F5=1,가정!$C$16,가정!$C$40) -> 31846 | U5: =S5*T5/10000 -> 230.39439 | V5: =U5/(1-가정!$C$41)*가정!$C$42 -> 242.52041 | W5: =가정!$C$33+N5+K5 -> 425.95 | X5: =X4+J5-K5 -> 635.95 | Y5: =W5+X5 -> 1061.9 | Z5: =O5*P5 -> 72.346414
A6: 3 | B6: 2027 | C6: 3 | D6: =가정!$F$6*MIN(1,MAX(0,(A6-가정!$C$28+1)/가정!$C$30)) -> 0 | E6: =IF(가정!$F$7<30000,1,0)*MIN(1,MAX(0,(A6-가정!$C$29+1)/가정!$C$30)) -> 0 | F6: =IF(가정!$F$7<30000,1,0)*IF(A6>=가정!$C$29,1,0) -> 0 | G6: =가정!$F$8*MIN(1,MAX(0,(A6-가정!$C$31+1)/가정!$C$32)) -> 0 | H6: =가정!$C$37+D6*가정!$C$14+E6*가정!$C$18 -> -0.005 | I6: =I5*(1+H6) -> 19.8005 | J6: =I6*(1+G6*가정!$C$19) -> 19.8005 | K6: =I6*가정!$C$36*(1+G6*가정!$C$19*가정!$C$24) -> 9.90025 | L6: =가정!$C$38+D6*가정!$C$12+E6*가정!$C$17 -> 0.111 | M6: =가정!$C$38+가정!$C$23*(L6-가정!$C$38) -> 0.111 | N6: =N5+K5 -> 19.95 | O6: =K6+가정!$C$33*M6+N6*L6 -> 57.1807 | P6: =가정!$C$39*(1+D6*가정!$C$13) -> 1.289 | Q6: =1+F6*가정!$C$15 -> 1 | R6: =P6*Q6 -> 1.289 | S6: =O6*R6 -> 73.705922 | T6: =IF(F6=1,가정!$C$16,가정!$C$40) -> 31846 | U6: =S6*T6/10000 -> 234.72388 | V6: =U6/(1-가정!$C$41)*가정!$C$42 -> 247.07777 | W6: =가정!$C$33+N6+K6 -> 435.85025 | X6: =X5+J6-K6 -> 645.85025 | Y6: =W6+X6 -> 1081.7005 | Z6: =O6*P6 -> 73.705922
A7: 4 | B7: 2027 | C7: 4 | D7: =가정!$F$6*MIN(1,MAX(0,(A7-가정!$C$28+1)/가정!$C$30)) -> 0 | E7: =IF(가정!$F$7<30000,1,0)*MIN(1,MAX(0,(A7-가정!$C$29+1)/가정!$C$30)) -> 0 | F7: =IF(가정!$F$7<30000,1,0)*IF(A7>=가정!$C$29,1,0) -> 0 | G7: =가정!$F$8*MIN(1,MAX(0,(A7-가정!$C$31+1)/가정!$C$32)) -> 0 | H7: =가정!$C$37+D7*가정!$C$14+E7*가정!$C$18 -> -0.005 | I7: =I6*(1+H7) -> 19.701497 | J7: =I7*(1+G7*가정!$C$19) -> 19.701497 | K7: =I7*가정!$C$36*(1+G7*가정!$C$19*가정!$C$24) -> 9.8507487 | L7: =가정!$C$38+D7*가정!$C$12+E7*가정!$C$17 -> 0.111 | M7: =가정!$C$38+가정!$C$23*(L7-가정!$C$38) -> 0.111 | N7: =N6+K6 -> 29.85025 | O7: =K7+가정!$C$33*M7+N7*L7 -> 58.230127 | P7: =가정!$C$39*(1+D7*가정!$C$13) -> 1.289 | Q7: =1+F7*가정!$C$15 -> 1 | R7: =P7*Q7 -> 1.289 | S7: =O7*R7 -> 75.058633 | T7: =IF(F7=1,가정!$C$16,가정!$C$40) -> 31846 | U7: =S7*T7/10000 -> 239.03172 | V7: =U7/(1-가정!$C$41)*가정!$C$42 -> 251.61234 | W7: =가정!$C$33+N7+K7 -> 445.701 | X7: =X6+J7-K7 -> 655.701 | Y7: =W7+X7 -> 1101.402 | Z7: =O7*P7 -> 75.058633
A8: 5 | B8: 2027 | C8: 5 | D8: =가정!$F$6*MIN(1,MAX(0,(A8-가정!$C$28+1)/가정!$C$30)) -> 0 | E8: =IF(가정!$F$7<30000,1,0)*MIN(1,MAX(0,(A8-가정!$C$29+1)/가정!$C$30)) -> 0 | F8: =IF(가정!$F$7<30000,1,0)*IF(A8>=가정!$C$29,1,0) -> 0 | G8: =가정!$F$8*MIN(1,MAX(0,(A8-가정!$C$31+1)/가정!$C$32)) -> 0.083333333 | H8: =가정!$C$37+D8*가정!$C$14+E8*가정!$C$18 -> -0.005 | I8: =I7*(1+H8) -> 19.60299 | J8: =I8*(1+G8*가정!$C$19) -> 20.060393 | K8: =I8*가정!$C$36*(1+G8*가정!$C$19*가정!$C$24) -> 10.030197 | L8: =가정!$C$38+D8*가정!$C$12+E8*가정!$C$17 -> 0.111 | M8: =가정!$C$38+가정!$C$23*(L8-가정!$C$38) -> 0.111 | N8: =N7+K7 -> 39.700999 | O8: =K8+가정!$C$33*M8+N8*L8 -> 59.503007 | P8: =가정!$C$39*(1+D8*가정!$C$13) -> 1.289 | Q8: =1+F8*가정!$C$15 -> 1 | R8: =P8*Q8 -> 1.289 | S8: =O8*R8 -> 76.699377 | T8: =IF(F8=1,가정!$C$16,가정!$C$40) -> 31846 | U8: =S8*T8/10000 -> 244.25683 | V8: =U8/(1-가정!$C$41)*가정!$C$42 -> 257.11246 | W8: =가정!$C$33+N8+K8 -> 455.7312 | X8: =X7+J8-K8 -> 665.7312 | Y8: =W8+X8 -> 1121.4624 | Z8: =O8*P8 -> 76.699377
A9: 6 | B9: 2027 | C9: 6 | D9: =가정!$F$6*MIN(1,MAX(0,(A9-가정!$C$28+1)/가정!$C$30)) -> 0.020833333 | E9: =IF(가정!$F$7<30000,1,0)*MIN(1,MAX(0,(A9-가정!$C$29+1)/가정!$C$30)) -> 0 | F9: =IF(가정!$F$7<30000,1,0)*IF(A9>=가정!$C$29,1,0) -> 0 | G9: =가정!$F$8*MIN(1,MAX(0,(A9-가정!$C$31+1)/가정!$C$32)) -> 0.16666667 | H9: =가정!$C$37+D9*가정!$C$14+E9*가정!$C$18 -> -0.0049583333 | I9: =I8*(1+H9) -> 19.505792 | J9: =I9*(1+G9*가정!$C$19) -> 20.416062 | K9: =I9*가정!$C$36*(1+G9*가정!$C$19*가정!$C$24) -> 10.208031 | L9: =가정!$C$38+D9*가정!$C$12+E9*가정!$C$17 -> 0.11139583 | M9: =가정!$C$38+가정!$C$23*(L9-가정!$C$38) -> 0.11139583 | N9: =N8+K8 -> 49.731195 | O9: =K9+가정!$C$33*M9+N9*L9 -> 60.974587 | P9: =가정!$C$39*(1+D9*가정!$C$13) -> 1.2943708 | Q9: =1+F9*가정!$C$15 -> 1 | R9: =P9*Q9 -> 1.2943708 | S9: =O9*R9 -> 78.923727 | T9: =IF(F9=1,가정!$C$16,가정!$C$40) -> 31846 | U9: =S9*T9/10000 -> 251.3405 | V9: =U9/(1-가정!$C$41)*가정!$C$42 -> 264.56895 | W9: =가정!$C$33+N9+K9 -> 465.93923 | X9: =X8+J9-K9 -> 675.93923 | Y9: =W9+X9 -> 1141.8785 | Z9: =O9*P9 -> 78.923727
A10: 7 | B10: 2027 | C10: 7 | D10: =가정!$F$6*MIN(1,MAX(0,(A10-가정!$C$28+1)/가정!$C$30)) -> 0.041666667 | E10: =IF(가정!$F$7<30000,1,0)*MIN(1,MAX(0,(A10-가정!$C$29+1)/가정!$C$30)) -> 0.020833333 | F10: =IF(가정!$F$7<30000,1,0)*IF(A10>=가정!$C$29,1,0) -> 1 | G10: =가정!$F$8*MIN(1,MAX(0,(A10-가정!$C$31+1)/가정!$C$32)) -> 0.25 | H10: =가정!$C$37+D10*가정!$C$14+E10*가정!$C$18 -> -0.004875 | I10: =I9*(1+H10) -> 19.410701 | J10: =I10*(1+G10*가정!$C$19) -> 20.76945 | K10: =I10*가정!$C$36*(1+G10*가정!$C$19*가정!$C$24) -> 10.384725 | L10: =가정!$C$38+D10*가정!$C$12+E10*가정!$C$17 -> 0.11220833 | M10: =가정!$C$38+가정!$C$23*(L10-가정!$C$38) -> 0.11220833 | N10: =N9+K9 -> 59.939226 | O10: =K10+가정!$C$33*M10+N10*L10 -> 62.666989 | P10: =가정!$C$39*(1+D10*가정!$C$13) -> 1.2997417 | Q10: =1+F10*가정!$C$15 -> 1.086 | R10: =P10*Q10 -> 1.4115194 | S10: =O10*R10 -> 88.455674 | T10: =IF(F10=1,가정!$C$16,가정!$C$40) -> 29800 | U10: =S10*T10/10000 -> 263.59791 | V10: =U10/(1-가정!$C$41)*가정!$C$42 -> 277.47148 | W10: =가정!$C$33+N10+K10 -> 476.32395 | X10: =X9+J10-K10 -> 686.32395 | Y10: =W10+X10 -> 1162.6479 | Z10: =O10*P10 -> 81.450897
A11: 8 | B11: 2027 | C11: 8 | D11: =가정!$F$6*MIN(1,MAX(0,(A11-가정!$C$28+1)/가정!$C$30)) -> 0.0625 | E11: =IF(가정!$F$7<30000,1,0)*MIN(1,MAX(0,(A11-가정!$C$29+1)/가정!$C$30)) -> 0.041666667 | F11: =IF(가정!$F$7<30000,1,0)*IF(A11>=가정!$C$29,1,0) -> 1 | G11: =가정!$F$8*MIN(1,MAX(0,(A11-가정!$C$31+1)/가정!$C$32)) -> 0.33333333 | H11: =가정!$C$37+D11*가정!$C$14+E11*가정!$C$18 -> -0.0047916667 | I11: =I10*(1+H11) -> 19.317692 | J11: =I11*(1+G11*가정!$C$19) -> 21.120676 | K11: =I11*가정!$C$36*(1+G11*가정!$C$19*가정!$C$24) -> 10.560338 | L11: =가정!$C$38+D11*가정!$C$12+E11*가정!$C$17 -> 0.11302083 | M11: =가정!$C$38+가정!$C$23*(L11-가정!$C$38) -> 0.11302083 | N11: =N10+K10 -> 70.323951 | O11: =K11+가정!$C$33*M11+N11*L11 -> 64.394868 | P11: =가정!$C$39*(1+D11*가정!$C$13) -> 1.3051125 | Q11: =1+F11*가정!$C$15 -> 1.086 | R11: =P11*Q11 -> 1.4173522 | S11: =O11*R11 -> 91.270206 | T11: =IF(F11=1,가정!$C$16,가정!$C$40) -> 29800 | U11: =S11*T11/10000 -> 271.98521 | V11: =U11/(1-가정!$C$41)*가정!$C$42 -> 286.30023 | W11: =가정!$C$33+N11+K11 -> 486.88429 | X11: =X10+J11-K11 -> 696.88429 | Y11: =W11+X11 -> 1183.7686 | Z11: =O11*P11 -> 84.042547
A12: 9 | B12: 2027 | C12: 9 | D12: =가정!$F$6*MIN(1,MAX(0,(A12-가정!$C$28+1)/가정!$C$30)) -> 0.083333333 | E12: =IF(가정!$F$7<30000,1,0)*MIN(1,MAX(0,(A12-가정!$C$29+1)/가정!$C$30)) -> 0.0625 | F12: =IF(가정!$F$7<30000,1,0)*IF(A12>=가정!$C$29,1,0) -> 1 | G12: =가정!$F$8*MIN(1,MAX(0,(A12-가정!$C$31+1)/가정!$C$32)) -> 0.41666667 | H12: =가정!$C$37+D12*가정!$C$14+E12*가정!$C$18 -> -0.0047083333 | I12: =I11*(1+H12) -> 19.226737 | J12: =I12*(1+G12*가정!$C$19) -> 21.469857 | K12: =I12*가정!$C$36*(1+G12*가정!$C$19*가정!$C$24) -> 10.734928 | L12: =가정!$C$38+D12*가정!$C$12+E12*가정!$C$17 -> 0.11383333 | M12: =가정!$C$38+가정!$C$23*(L12-가정!$C$38) -> 0.11383333 | N12: =N11+K11 -> 80.884289 | O12: =K12+가정!$C$33*M12+N12*L12 -> 66.15859 | P12: =가정!$C$39*(1+D12*가정!$C$13) -> 1.3104833 | Q12: =1+F12*가정!$C$15 -> 1.086 | R12: =P12*Q12 -> 1.4231849 | S12: =O12*R12 -> 94.155906 | T12: =IF(F12=1,가정!$C$16,가정!$C$40) -> 29800 | U12: =S12*T12/10000 -> 280.5846 | V12: =U12/(1-가정!$C$41)*가정!$C$42 -> 295.35221 | W12: =가정!$C$33+N12+K12 -> 497.61922 | X12: =X11+J12-K12 -> 707.61922 | Y12: =W12+X12 -> 1205.2384 | Z12: =O12*P12 -> 86.69973
A13: 10 | B13: 2027 | C13: 10 | D13: =가정!$F$6*MIN(1,MAX(0,(A13-가정!$C$28+1)/가정!$C$30)) -> 0.10416667 | E13: =IF(가정!$F$7<30000,1,0)*MIN(1,MAX(0,(A13-가정!$C$29+1)/가정!$C$30)) -> 0.083333333 | F13: =IF(가정!$F$7<30000,1,0)*IF(A13>=가정!$C$29,1,0) -> 1 | G13: =가정!$F$8*MIN(1,MAX(0,(A13-가정!$C$31+1)/가정!$C$32)) -> 0.5 | H13: =가정!$C$37+D13*가정!$C$14+E13*가정!$C$18 -> -0.004625 | I13: =I12*(1+H13) -> 19.137814 | J13: =I13*(1+G13*가정!$C$19) -> 21.817108 | K13: =I13*가정!$C$36*(1+G13*가정!$C$19*가정!$C$24) -> 10.908554 | L13: =가정!$C$38+D13*가정!$C$12+E13*가정!$C$17 -> 0.11464583 | M13: =가정!$C$38+가정!$C$23*(L13-가정!$C$38) -> 0.11464583 | N13: =N12+K12 -> 91.619218 | O13: =K13+가정!$C$33*M13+N13*L13 -> 67.958524 | P13: =가정!$C$39*(1+D13*가정!$C$13) -> 1.3158542 | Q13: =1+F13*가정!$C$15 -> 1.086 | R13: =P13*Q13 -> 1.4290176 | S13: =O13*R13 -> 97.113928 | T13: =IF(F13=1,가정!$C$16,가정!$C$40) -> 29800 | U13: =S13*T13/10000 -> 289.39951 | V13: =U13/(1-가정!$C$41)*가정!$C$42 -> 304.63106 | W13: =가정!$C$33+N13+K13 -> 508.52777 | X13: =X12+J13-K13 -> 718.52777 | Y13: =W13+X13 -> 1227.0555 | Z13: =O13*P13 -> 89.423507
A14: 11 | B14: 2027 | C14: 11 | D14: =가정!$F$6*MIN(1,MAX(0,(A14-가정!$C$28+1)/가정!$C$30)) -> 0.125 | E14: =IF(가정!$F$7<30000,1,0)*MIN(1,MAX(0,(A14-가정!$C$29+1)/가정!$C$30)) -> 0.10416667 | F14: =IF(가정!$F$7<30000,1,0)*IF(A14>=가정!$C$29,1,0) -> 1 | G14: =가정!$F$8*MIN(1,MAX(0,(A14-가정!$C$31+1)/가정!$C$32)) -> 0.58333333 | H14: =가정!$C$37+D14*가정!$C$14+E14*가정!$C$18 -> -0.0045416667 | I14: =I13*(1+H14) -> 19.050896 | J14: =I14*(1+G14*가정!$C$19) -> 22.162543 | K14: =I14*가정!$C$36*(1+G14*가정!$C$19*가정!$C$24) -> 11.081271 | L14: =가정!$C$38+D14*가정!$C$12+E14*가정!$C$17 -> 0.11545833 | M14: =가정!$C$38+가정!$C$23*(L14-가정!$C$38) -> 0.11545833 | N14: =N13+K13 -> 102.52777 | O14: =K14+가정!$C$33*M14+N14*L14 -> 69.79504 | P14: =가정!$C$39*(1+D14*가정!$C$13) -> 1.321225 | Q14: =1+F14*가정!$C$15 -> 1.086 | R14: =P14*Q14 -> 1.4348504 | S14: =O14*R14 -> 100.14544 | T14: =IF(F14=1,가정!$C$16,가정!$C$40) -> 29800 | U14: =S14*T14/10000 -> 298.4334 | V14: =U14/(1-가정!$C$41)*가정!$C$42 -> 314.14043 | W14: =가정!$C$33+N14+K14 -> 519.60904 | X14: =X13+J14-K14 -> 729.60904 | Y14: =W14+X14 -> 1249.2181 | Z14: =O14*P14 -> 92.214952
A15: 12 | B15: 2027 | C15: 12 | D15: =가정!$F$6*MIN(1,MAX(0,(A15-가정!$C$28+1)/가정!$C$30)) -> 0.14583333 | E15: =IF(가정!$F$7<30000,1,0)*MIN(1,MAX(0,(A15-가정!$C$29+1)/가정!$C$30)) -> 0.125 | F15: =IF(가정!$F$7<30000,1,0)*IF(A15>=가정!$C$29,1,0) -> 1 | G15: =가정!$F$8*MIN(1,MAX(0,(A15-가정!$C$31+1)/가정!$C$32)) -> 0.66666667 | H15: =가정!$C$37+D15*가정!$C$14+E15*가정!$C$18 -> -0.0044583333 | I15: =I14*(1+H15) -> 18.965961 | J15: =I15*(1+G15*가정!$C$19) -> 22.506274 | K15: =I15*가정!$C$36*(1+G15*가정!$C$19*가정!$C$24) -> 11.253137 | L15: =가정!$C$38+D15*가정!$C$12+E15*가정!$C$17 -> 0.11627083 | M15: =가정!$C$38+가정!$C$23*(L15-가정!$C$38) -> 0.11627083 | N15: =N14+K14 -> 113.60904 | O15: =K15+가정!$C$33*M15+N15*L15 -> 71.668513 | P15: =가정!$C$39*(1+D15*가정!$C$13) -> 1.3265958 | Q15: =1+F15*가정!$C$15 -> 1.086 | R15: =P15*Q15 -> 1.4406831 | S15: =O15*R15 -> 103.25161 | T15: =IF(F15=1,가정!$C$16,가정!$C$40) -> 29800 | U15: =S15*T15/10000 -> 307.68981 | V15: =U15/(1-가정!$C$41)*가정!$C$42 -> 323.88401 | W15: =가정!$C$33+N15+K15 -> 530.86218 | X15: =X14+J15-K15 -> 740.86218 | Y15: =W15+X15 -> 1271.7244 | Z15: =O15*P15 -> 95.075151
